Workbook
Name aaaa: #REF!
Name aaaa: #REF!
Name aaaaa: #REF!
Name aaaaa: #REF!
Name anomalies: #REF!
Name anomalies: #REF!
Name CAP_01__02__03__04__Clientèle_de_détail___Pas_de_données_complémentaires_obligatoires_associées_à_ces_CAP__Les_expositions_sur_la_Clientèle_de_détail_sont_pondérées_à_75_.: #REF!
Name CAP_01__02__03__04__Clientèle_de_détail___Pas_de_données_complémentaires_obligatoires_associées_à_ces_CAP__Les_expositions_sur_la_Clientèle_de_détail_sont_pondérées_à_75_.: #REF!
Name CAP_de_l_exposition: #REF!
Name CAP_de_l_exposition: #REF!
Name CAPtest: '[1]A1 Degraded Data Entry'!#REF!
Name CAPtest: '[1]A1 Degraded Data Entry'!#REF!
Name Groupe_caractéristiques: #REF!
Name Groupe_caractéristiques: #REF!
Name Groupe_caractéristiques: #REF!
Name Méthodo_CAP: #REF!
Name Méthodo_CAP: #REF!
Name Méthodo_Conditions_réglementaires: #REF!
Name Méthodo_Conditions_réglementaires: #REF!
Name Méthodo_Crédit_bail: #REF!
Name Méthodo_Crédit_bail: #REF!
Name Méthodo_DeterminationCAP: #REF!
Name Méthodo_DeterminationCAP: #REF!
Name Méthodo_douteux_impayé: #REF!
Name Méthodo_douteux_impayé: #REF!
Name Méthodo_engagement: #REF!
Name Méthodo_engagement: #REF!
Name Méthodo_impayé: #REF!
Name Méthodo_impayé: #REF!
Name Méthodo_indicateur: #REF!
Name Méthodo_indicateur: #REF!
Name Méthodo_indicateur_couverture: [2]Méthodologie!#REF!
Name Méthodo_indicateur_couverture: [2]Méthodologie!#REF!
Name Méthodo_indicateur_couverture: [2]Méthodologie!#REF!
Name Méthodo_indicateur_couverture: [2]Méthodologie!#REF!
Name Méthodo_Montants: #REF!
Name Méthodo_Montants: #REF!
Name Méthodo_NATO: #REF!
Name Méthodo_NATO: #REF!
Name Méthodo_PNU: #REF!
Name Méthodo_PNU: #REF!
Name Méthodo_Pond_pref: #REF!
Name Méthodo_Pond_pref: #REF!
Name méthodo_provisions: #REF!
Name méthodo_provisions: #REF!
Name Méthodo_sûretés: #REF!
Name Méthodo_sûretés: #REF!
Name Méthodo_Tiers_Agrégat: #REF!
Name Méthodo_Tiers_Agrégat: #REF!
Name Méthodo_usage_bien_immo: #REF!
Name Méthodo_usage_bien_immo: #REF!
Name Objets: '[3]Liste des objets'!$A:$A
Name Règles_corr: #REF!
Name Règles_corr: #REF!
Name test: #REF!
Name test: #REF!
Name test: #REF!
Name Tiers_Agrégat: #REF!
Name Tiers_Agrégat: #REF!
Name Toto: #REF!

Sheet Modifications
A1: Modifications
H2: Nombre de contrôles par type et sévérité
A3: Emetteur / Issuer | C3: Crédit Agricole SA : Programme Convergence Finances Risques (Crédit Agricole SA/FIG/DOP/CFR) | H3: 7 | I3: 6 | J3: 5 | K3: Mix | L3: total
A4: Date de diffusion / Publication date | C4: Lorsque cette date est renseignée, cela signifie que la notice est publiée dans https://service.ca-mocca.com/maia-collab/CFR/SitePages/Notices.aspx qui reprend l'ensemble des versions publiées. | G4: Présence | H4: =COUNTIF('A1 Alimentation Adaptée'!$AP$4:$AP$121,$H$3) -> 30 | I4: =COUNTIF('A1 Alimentation Adaptée'!$AP$4:$AP$121,$I$3) -> 26 | J4: =COUNTIF('A1 Alimentation Adaptée'!$AP$4:$AP$121,$J$3) -> 0 | K4: =L4-SUM(H4:J4) -> 2 | L4: =COUNTA('A1 Alimentation Adaptée'!$AP$4:$AP$121) -> 58
C5: You can find all the published versions on https://service.ca-mocca.com/maia-collab/CFR/SitePages/Notices_EN.aspx | G5: Référentiel | H5: =COUNTIF('A1 Alimentation Adaptée'!$AT$4:$AT$129,$H$3) -> 51 | I5: =COUNTIF('A1 Alimentation Adaptée'!$AT$4:$AT$129,$I$3) -> 0 | J5: =COUNTIF('A1 Alimentation Adaptée'!$AT$4:$AT$129,$J$3) -> 0 | K5: =L5-SUM(H5:J5) -> 0 | L5: =COUNTA('A1 Alimentation Adaptée'!$AT$4:$AT$129) -> 51
A6: Descriptif de la Mise à jour / Modifications | C6: Descriptif de la modification / Modification description | G6: Valeur | H6: =COUNTIF('A1 Alimentation Adaptée'!$AX$3:$AX$122,$H$3) -> 17 | I6: =COUNTIF('A1 Alimentation Adaptée'!$AX$3:$AX$122,I3) -> 7 | J6: =COUNTIF('A1 Alimentation Adaptée'!$AX$3:$AX$122,J3) -> 0 | K6: =L6-SUM(H6:J6) -> 1 | L6: =COUNTA('A1 Alimentation Adaptée'!$AX$3:$AX$122) -> 25
A7: Couleur / Color | C7: Permet d'identifier les zones ajoutées/modifiées | G7: Intra-objet | H7: =COUNTIF('A1 Alimentation Adaptée'!$BB$4:$BB$126,$H$3) -> 7 | I7: =COUNTIF('A1 Alimentation Adaptée'!$BB$4:$BB$126,I3) -> 5 | J7: =COUNTIF('A1 Alimentation Adaptée'!$BB$4:$BB$126,J3) -> 0 | K7: =L7-SUM(H7:J7) -> 0 | L7: =COUNTA('A1 Alimentation Adaptée'!$BB$4:$BB$126) -> 12
C8: The color code enables identification of the different kinds of evolutions | G8: Inter-objet | H8: =COUNTIF('A1 Alimentation Adaptée'!$BF$5:$BF$125,$H$3) -> 6 | I8: =COUNTIF('A1 Alimentation Adaptée'!$BF$5:$BF$125,I3) -> 0 | J8: =COUNTIF('A1 Alimentation Adaptée'!$BF$5:$BF$125,J3) -> 0 | K8: =L8-SUM(H8:J8) -> 0 | L8: =COUNTA('A1 Alimentation Adaptée'!$BF$5:$BF$125) -> 6
G9: Cohérence | H9: =COUNTIF('A1 Alimentation Adaptée'!$BJ$3:$BJ$124,Modifications!$H$3) -> 0 | I9: =COUNTIF('A1 Alimentation Adaptée'!$BJ$3:$BJ$124,Modifications!$I$3) -> 3 | J9: =COUNTIF('A1 Alimentation Adaptée'!$BJ$3:$BJ$124,Modifications!$J$3) -> 0 | K9: =L9-SUM(H9:J9) -> 0 | L9: =COUNTA('A1 Alimentation Adaptée'!$BJ$3:$BJ$124) -> 3
A12: Suivi des versions / Version tracking
A13: Date de diffusion / Publication date | B13: Publication mocca n° | C13: Descriptif de la mise à jour / Modifications | D13: Couleur / Color
A14: 46014 | B14: 45.00 | C14: Ajout de nouvelles données / New data addition
A15: 46014 | B15: 45.00 | C15: Ajouter des séparateurs ';' entre chaque donnée / Semicolon ';' to be added between each data
A16: 46014 | B16: 45.00 | C16: Modifications / Modifications
A19: Liens utiles / Useful Links
A20: Langages Communs / Common Languages | C20: https://service.ca-mocca.com/maia-collab/CFR/SitePages/Langages_Communs.aspx https://service.ca-mocca.com/maia-collab/CFR/SitePages/Common_Languages.aspx
A21: Manuel des Echanges Entités-Zone de Partage et Notices / Exchange Manual ZP-entities and Notices | C21: https://service.ca-mocca.com/maia-collab/CFR/SitePages/Notices.aspx https://service.ca-mocca.com/maia-collab/CFR/SitePages/Notices_EN.aspx
A22: Guide Méthodologique - Alimentation PACT (ex CRR) / Methodological Guide - PACT (ex CRR) Feeding | C22: https://service.ca-mocca.com/maia-collab/CFR/SitePages/Notices.aspx https://service.ca-mocca.com/maia-collab/CFR/SitePages/Notices_EN.aspx

Sheet A1 Alimentation Adaptée
AN1: CTRL PRESENCE / PRESENCE CTRL | AR1: CTRL REFERENTIEL / REFERENTIEL CTRL - CIBLE | AV1: CTRL VALEUR / VALUE CTRL - CIBLE | AZ1: CTRL INTRA-OBJET / INTRA-OBJECT CTRL - CIBLE | BD1: CTRL INTER-OBJET / INTER-OBJECT CTRL | BH1: CTRL COHERENCE (cf. onglet dédié) / CONSISTENCY CTRL (cf. dedicated tab)
A2: OBJET DE COLLECTE / COLLECTION OBJECT | B2: N° D'ORDRE TECHNIQUE DE LA DONNEE / TECHNICAL ORDER NUMBER OF THE DATA IN THE FILE | C2: BLOC DE DONNEES | D2: DATA BLOCK | E2: REFERENCE DE COLLECTE / COLLECTION REFERENCE | F2: NOM DE LA DONNEE | G2: DATA NAME | H2: DEFINITION | I2: DEFINITION | J2: Inclus CALF | K2: Provenance | L2: Table DDR | M2: RG | N2: Commentaire | O2: Version | P2: TERME METIER | Q2: BUSINESS TERM | R2: CODE TECHNIQUE / TECHNICAL CODE | S2: EXIGENCE D'ALIMENTATION | T2: SUPPLY REQUIREMENT | U2: REFERENCE DE LANGAGE COMMUN / COMMON LANGUAGE REFERENCE | V2: TABLE START / START Table | W2: REGLE DE GESTION | X2: MANAGEMENT RULE | Y2: FORMAT | Z2: REGLE DE FORMATAGE | AA2: FORMATTING RULE | AB2: LONGUEUR / LENGTH | AC2: POSITION / POSITION | AD2: VERSION DE CREATION / FIRST APPEARANCE VERSION | AE2: VERSION DE DERNIERE APPARITION / LAST APPEARANCE VERSION | AF2: VERSION DE MODIFICATION / MODIFICATION VERSION | AG2: USAGE(S) DECLARE(S) / DECLARED USAGE | AH2: DONNEE CRITIQUE POUR / CRITICAL DATA FOR | AI2: DONNEE A CARACTERE PERSONNEL / PERSONNAL DATA | AJ2: PERIMETRE DE COLLECTE / COLLECTION SCOPE | AK2: APPLICATION REMETTANTE / REMITTING APPLICATION | AL2: REFERENCE DE LA DONNEE DANS L'APPLICATION REMETTANTE / DATA REFERENCE IN REMITTING APPLICATION | AN2: CTRL PRESENCE | AO2: PRESENCE CTRL | AP2: PRESENCE SCORE CONSEQUENCE | AQ2: PRESENCE Code CTRL ZP | AR2: CTRL REFERENTIEL | AS2: REFERENTIEL CTRL | AT2: REFERENTIEL SCORE CONSEQUENCE | AU2: REFERENTIEL Code CTRL ZP | AV2: CTRL VALEUR | AW2: VALUE CTRL | AX2: VALEUR SCORE CONSEQUENCE | AY2: VALEUR Code CTRL ZP | AZ2: CTRL INTRA-OBJET | BA2: INTRA-OBJECT CTRL | BB2: COHERENCE SCORE CONSEQUENCE | BC2: COHERENCE Code CTRL ZP | BD2: CTRL INTER-OBJET | BE2: INTER-OBJECT CTRL | BF2: SCORE CONSEQUENCE | BG2: Code CTRL ZP | BH2: CTRL COHERENCE | BI2: CONSISTENCY CTRL | BJ2: Score Consequence | BK2: Code CTRL ZP
A3: Famille de flux et Objet de Collecte véhiculant la donnée / Flow family and data collection object | B3: Numéro séquentiel correspondant au numéro d'ordre de la donnée dans le fichier physique. Invariant dans le temps (toute nouvelle donnée sera ajoutée en fin de fichier) / Sequential number corresponding to the order number of the data in the physical file. Invariant in time (any new data will be added at the end of the file) | C3: Classification de la donnée dans un des blocs structurant l'Objet de Collecte | D3: Classification of the data in one of the blocks structuring the Collection Object. | E3: Référence de la donnée collectée via l'Objet de Collecte. Attribut communément appelé 'Etiquette' / Reference of the data collected via the Collection Object. Attribute commonly referred to as 'Label' | F3: Libellé Métier de la donnée | G3: Data business name | H3: Définition métier de la donnée | I3: Business data definition | P3: Terme métier parent du glossaire métier auquel se rapporte la donnée | Q3: Term parent business of the business glossary to which the data relates | R3: Nom technique de la donnée / Technical name of the data | S3: Exigence de présence de la donnée sur le périmètre de Collecte défini. L'information prend la valeur : - Obligatoire si la donnée est exigée - Obligatoire Si si la donnée est exigée dans des conditions définies dans la Règle de Gestion - Facultatif si la donnée n'est pas exigée - NA si la donnée est devenue obsolète et n'est plus collectée sur le domaine de Collecte - A renseigner si l'information n'est pas encore disponible | T3: Requirement to have the data on the defined Collection perimeter. Information is valued: - Mandatory if data is required - Mandatory If the data is required under conditions defined in the Management Rule - Optional if data is not required - NA if the data has become obsolete and is no longer collected on the Collection domain - To be filled if the information is not yet available | U3: Référence du Langage Commun structurant le format autorisé et la nomenclature autorisée. L'information prend la valeur : - LC.NNNN si la donnée s'adosse au LC.NNNN - LC à référencer si la donnée s'adosse à un LC en cours de référencement - NA si la donnée ne s'adosse à aucun LC /A reference to the Common Language structuring the allowed format and the allowed nomenclature. Information is valued: - LC.NNNN if the data is based on LC.NNNN - LC to be referenced if the data is against an LC being referenced - NA if the data does not support any LC. | V3: Table(s)/Rubrique(s) Start porteuse(s) de la nomenclature du Langage Commun lorsque celui ci est référencé. Il peut être multiple. L'information prend la valeur : - TA XXXXX si la donnée s'adosse à la table TA XXXXX - RB XXXXX si la donnée s'adosse à la rubrique RB XXXXX - NA si la donnée ne s'adosse à aucun référentiel Start /Table(s)/Topic(s) Start carrying the nomenclature of the Common Language when it is referenced. It can be multiple. Information is valued: - TA XXXXX if the data is based on the table TA XXXXX - RB XXXXX if the data is based on RB XXXXX - NA if the data does not support any Start referential | W3: Précisions sur les exigences posées sur la donnée (de type seuils, formules, calculs, règles d'alimentation hors LC...) ou commentaires. En particulier, les exigences posées sur la donnée peuvent porter sur : - sa présence (dans le contrôle) (ne pas reprendre les conditions du contrôle de présence si assez explicite) Nota Bene sur le domaine de valeurs : -- si la donnée peut s'inscrire dans toute la nomenclature d'un Langage Commun, le LC est directement renseigné dans le champ dédié "Référence LC" -- si la donnée s'inscrit dans un domaine de valeurs plus restreint lié au périmètre fonctionnel de l'objet collecté, ce domaine de valeurs strictement autorisé est indiqué ici (contrôle de valeur). L'information prend la valeur NA sans exigences particulières | X3: Details on the requirements of the data (of the threshold type, formulas, calculations, rules of supply excluding LC...) or comments. In particular, the data requirements may relate to: - its presence (in the control) (do not take over the presence control conditions so explicitly) Note Bene on the value domain: — if the data can be inscribed in the entire nomenclature of a Common Language, the LC is directly filled in the dedicated field "LC Reference" — if the data falls within a narrower value domain related to the functional scope of the collected object, this strictly authorized value domain is indicated here (value control). Information is set to NA without any special requirements | Y3: Format de la donnée. L'information prend la valeur : - DATE - ALPHA - NUM - A renseigner si l'information n'est pas encore disponible Data format. Information is valued: - DATE - ALPHA - NUM - To be filled if the information is not yet available | Z3: Structure de présentation des données de type date, montant et taux. L'information prend la valeur : - "NA" en l'absence de règle de formatage. - "A renseigner" si l'information n'est pas disponible | AA3: Date, amount and rate data presentation structure. Information is valued: - "NA" in the absence of a formatting rule. - "To be filled" if the information is not available | AB3: Longueur de la donnée La valeur 8 est attendue sur les formats DATE/ Data length Value 8 is expected on DATE formats | AC3: Numéro correspondant à la position de la donnée dans la chaine de caractères du fichier physique. Nécessaire que pour les fichiers plats sans séparateurs (PACT par exemple). Elle prend la valeur NA dans les autres cas. / The number that corresponds to the position of the data item in the character string of the physical file. Required only for flat files without separators. It is set to NA in other cases. | AD3: Version de la notice dans laquelle la donnée est apparue. L'information prend la valeur: - De la donnée Verbloc figurant dans l'en-tête de la notice - A renseigner si l'information n'est pas encore disponible./ The version of the notice in which the data appeared. Information takes value: - Verbloc data in the header of the notice - To be filled if the information is not yet available. | AE3: Version de la notice dans laquelle la donnée apparaît pour la dernière fois. L'information prend la valeur: - De la donnée Verbloc figurant dans l'en-tête de la notice quand la donnée est devenue obsolète - NA quand la donnée est toujours collectée/ The version of the notice in which the data last appears. Information takes value: - Verbloc data in the header of the record when the data has become obsolete - NA when data is still collected | AF3: Dernière version de publication de la notice présentant la MAJ de la donnée / Latest publication version of the notice where the data was updated | AG3: Liste des usages industriels déclarant exploiter la donnée. L'information prend la valeur : - Usage1, Usage2, Usage3, ..., UsageN si plusieurs usages sont déclarés - NA en l'absence d'usage déclaré - A renseigner si l'information n'est pas encore disponible /List of industrial uses declaring to exploit the data. Information is valued: - Use1, Use2, Use3, ..., UseN if more than one use is declared - NA in the absence of declared use - To be filled if the information is not yet available | AH3: Liste des usages signalant que la donnée est indispensable pour leur fonctionnement. Le processus de production de reporting de ce(s) usage(s) est compromis par l'absence de cette donnée ou par sa non qualité. L'information prend la valeur : - Usage1, Usage2, Usage3, ..., UsageN si plusieurs usages ont déclaré la donnée critique - NA en l'absence de criticité de la donnée quel que soit l'usage - A renseigner si l'information n'est pas encore disponible/ List of uses indicating that the data is essential for their operation. The reporting production process of this use(s) is compromised by the absence of this data or by its non-quality. Information is valued: - Usage1, Usage2, Usage3, ..., UsageN if several uses have declared critical data - NA in the absence of criticality of the data whatever the use - To be filled if the information is not yet available | AI3: Indicateur signalant que la donnée est à caractère personnel. Une donnée à caractère personnel au sens RGPD est une information se rapportant à une personne physique identifiée ou identifiable. Elle peut permettre d'identifier une personne physique directement (exemple : nom et prénom) ou indirectement (exemple : par un numéro de téléphone ou de plaque d'immatriculation, un identifiant tel que le numéro de sécurité sociale, une adresse postale ou courriel). L'information prend la valeur : - Y si la donnée est une donnée à caractère personnel - N dans le cas contraire - A renseigner si l'information n'est pas encore disponible/ Indicator indicating that the data is personal. Personal data in the sense of GDPR is information relating to an identified or identifiable natural person. It can identify a natural person directly (example: first and last names) or indirectly (example: by a telephone or license plate number, an identifier such as a social security number, a postal or email address). Information is valued: - Y if the data is personal data - N otherwise - To be filled if the information is not yet available | AJ3: Information concernant les données du P1, M1 et flux passifs seulement. Le périmètre de Collecte précise le domaine fonctionnel auquel se rapporte la Collecte de la donnée. La nature du domaine fonctionnel varie suivant les objets de collecte. L'information peut être de nature: - Type de risque - Nature juridique de la sûreté - NA dans les autres cas/ Information on P1, M1 and liability flow data only. The Collection scope specifies the functional area to which the Data Collection relates. The nature of the functional area varies according to the collection objects. The information may be of a nature: - Risk type - Legal nature of security interest - NA in other cases | AK3: Application en central qui met la donnée à disposition / Central application that makes data available | AL3: Référence de la donnée en provenance de l'application remettante / Reference of data from remitting application
A4: A1 | B4: 1 | C4: 00 - En-tête du flux | D4: 00 - File header | E4: A1 H.ENREG | F4: Type d'enregistrement | G4: Type of record | H4: Type d'enregistrement correspondant au bloc En-tête | I4: Type of record corresponding to Header block | P4: ND | Q4: ND | R4: ENREG | S4: Obligatoire | T4: Mandatory | U4: NA | V4: NA | W4: A alimenter à "00" | X4: To be filled with "00" | Y4: ALPHA | Z4: NA | AA4: NA | AB4: 2 | AC4: NA | AD4: 43 | AE4: NA | AF4: NA | AG4: USAGE ZP | AH4: NA | AI4: NA | AJ4: NA | AK4: NA | AL4: NA
A5: A1 | B5: 2 | C5: 00 - En-tête du flux | D5: 00 - File header | E5: A1 H.IDFICHIER | F5: Identifiant du fichier | G5: File's identifier | H5: Identifiant caractérisant le contenu véhiculé par le fichier et servant à référencer chaque type de fichier échangé dans le Référentiel des Echanges du Groupe afin de favoriser la réutilisation | I5: Identifier characterising the content reported by the file and serving to reference each type of file exchanged in the Group's Exchange Referential to facilitate re-use | P5: ND | Q5: ND | R5: IDFICHIER | S5: Obligatoire | T5: Mandatory | U5: NA | V5: NA | W5: A alimenter à "00000535" | X5: To be filled with "00000535" | Y5: ALPHA | Z5: NA | AA5: NA | AB5: 8 | AC5: NA | AD5: 43 | AE5: NA | AF5: NA | AG5: USAGE ZP | AH5: NA | AI5: NA | AJ5: NA | AK5: NA | AL5: NA
A6: A1 | B6: 3 | C6: 00 - En-tête du flux | D6: 00 - File header | E6: A1 H.VERFICHIER | F6: Version technique du fichier | G6: File's technical version | H6: Qualifie les modalités techniques de constitution du fichier (positionnel, XML, …) | I6: Characterises the technical modalities for producing the file (positional, XML, etc.) | P6: ND | Q6: ND | R6: VERFICHIER | S6: Obligatoire | T6: Mandatory | U6: NA | V6: NA | W6: A alimenter à "001" | X6: To be filled with "001" | Y6: ALPHA | Z6: NA | AA6: NA | AB6: 3 | AC6: NA | AD6: 43 | AE6: NA | AF6: NA | AG6: USAGE ZP | AH6: NA | AI6: NA | AJ6: NA | AK6: NA | AL6: NA
A7: A1 | B7: 4 | C7: 00 - En-tête du flux | D7: 00 - File header | E7: A1 H.TIMESTAMP | F7: Horodatage | G7: Timestamp | H7: Date et heure de production du fichier (norme ISO 8601 : séparateur normalisé « T » entre la date et l'heure) | I7: Date and time of the file's production (ISO 8601 standard: normalised separator “T” between the date and time) | P7: ND | Q7: ND | R7: TIMESTAMP | S7: Obligatoire | T7: Mandatory | U7: NA | V7: NA | W7: NA | X7: NA | Y7: ALPHA | Z7: AAAAMMJJTHHMMSS | AA7: YYYYMMDDTHHMMSS | AB7: 15 | AC7: NA | AD7: 43 | AE7: NA | AF7: NA | AG7: USAGE ZP | AH7: NA | AI7: NA | AJ7: NA | AK7: NA | AL7: NA
A8: A1 | B8: 5 | C8: 00 - En-tête du flux | D8: 00 - File header | E8: A1 H.UOE | F8: Entité émettrice | G8: Issuing entity | H8: Identifiant national de l'entité produisant le fichier (pour son propre compte ou en cas de sous-traitance pour le compte de l'entité déclarante) | I8: National identifier of the entity producing the file (for its own account or, in the event of subcontracting, on behalf of the issuing entity) | P8: ND | Q8: ND | R8: UOE | S8: Obligatoire | T8: Mandatory | U8: LC.0003 | V8: TA FI59 | W8: NA | X8: NA | Y8: ALPHA | Z8: NA | AA8: NA | AB8: 5 | AC8: NA | AD8: 43 | AE8: NA | AF8: NA | AG8: USAGE ZP | AH8: NA | AI8: NA | AJ8: NA | AK8: NA | AL8: NA
A9: A1 | B9: 6 | C9: 00 - En-tête du flux | D9: 00 - File header | E9: A1 H.UOD | F9: Entité déclarante | G9: Reporting entity | H9: Identifiant national de l'entité à laquelle se rapporte le contenu du fichier (entité porteuse du risque) | I9: National identifier of the entity to which the file's content relates (entity carrying the risk) | P9: ND | Q9: ND | R9: UOD | S9: Obligatoire | T9: Mandatory | U9: LC.0003 | V9: TA FI59 | W9: NA | X9: NA | Y9: ALPHA | Z9: NA | AA9: NA | AB9: 5 | AC9: NA | AD9: 43 | AE9: NA | AF9: NA | AG9: USAGE ZP | AH9: NA | AI9: NA | AJ9: NA | AK9: NA | AL9: NA
A10: A1 | B10: 7 | C10: 00 - En-tête du flux | D10: 00 - File header | E10: A1 H.NMAPPU | F10: Application émettrice | G10: Issuing application | H10: Code ou nom de l'application ou du job utilisés pour produire le fichier dans le SI de l'entité | I10: Code or name of the application or job used to produce the file in the entity's IT system | P10: ND | Q10: ND | R10: NMAPPU | S10: Facultatif | T10: Optional | U10: NA | V10: NA | W10: Non alimenté | X10: Not filled | Y10: ALPHA | Z10: NA | AA10: NA | AB10: 32 | AC10: NA | AD10: 43 | AE10: NA | AF10: NA | AG10: USAGE ZP | AH10: NA | AI10: NA | AJ10: NA | AK10: NA | AL10: NA
A11: A1 | B11: 8 | C11: 00 - En-tête du flux | D11: 00 - File header | E11: A1 H.CDBLOC | F11: Code du flux | G11: Flow code | H11: Code du flux correspondant aux objets métier véhiculés par le fichier | I11: Flow code corresponding to the business objects reported by the file | P11: ND | Q11: ND | R11: CDBLOC | S11: Obligatoire | T11: Mandatory | U11: NA | V11: NA | W11: A alimenter à "CRRA" | X11: To be filled with "CRRA" | Y11: ALPHA | Z11: NA | AA11: NA | AB11: 4 | AC11: NA | AD11: 43 | AE11: NA | AF11: NA | AG11: USAGE ZP | AH11: NA | AI11: NA | AJ11: NA | AK11: NA | AL11: NA
A12: A1 | B12: 9 | C12: 00 - En-tête du flux | D12: 00 - File header | E12: A1 H.VERBLOC | F12: Version du flux | G12: Flow version | H12: Version du flux correspondant aux objets métier véhiculés par le fichier | I12: Version of flow corresponding to the business objects reported by the file | J12: OUI | K12: NA | L12: NA | M12: Alimenter à '45' | N12: Il s'agit de la version du flux Elle sera alimenté à "45" | O12: Version 1 | P12: ND | Q12: ND | R12: VERBLOC | S12: Obligatoire | T12: Mandatory | U12: NA | V12: NA | W12: A alimenter à "45" | X12: To be filled with "45" | Y12: ALPHA | Z12: NA | AA12: NA | AB12: 2 | AC12: NA | AD12: 43 | AE12: NA | AF12: 45.00 | AG12: USAGE ZP | AH12: NA | AI12: NA | AJ12: NA | AK12: NA | AL12: NA
A13: A1 | B13: 10 | C13: 00 - En-tête du flux | D13: 00 - File header | E13: A1 H.NUMENV | F13: Numéro d'envoi du fichier | G13: File's dispatch number | H13: Permet de gérer les réemissions | I13: Serves to manage re-issues | P13: ND | Q13: ND | R13: NUMENV | S13: Obligatoire | T13: Mandatory | U13: NA | V13: NA | W13: A alimenter à "00001" et à incrémenter de +1 à chaque réémission | X13: To be filled with "00001"and incrementing by +1 at each reissue | Y13: ALPHA | Z13: NA | AA13: NA | AB13: 5 | AC13: NA | AD13: 43 | AE13: NA | AF13: NA | AG13: USAGE ZP | AH13: NA | AI13: NA | AJ13: NA | AK13: NA | AL13: NA
A14: A1 | B14: 11 | C14: 00 - En-tête du flux | D14: 00 - File header | E14: A1 H.CRARRETE | F14: Type d'arrêté | G14: Reporting type | H14: Périodicité de l'arrêté | I14: Reporting frequency | P14: ND | Q14: ND | R14: CRARRETE | S14: Obligatoire | T14: Mandatory | U14: LC.0056 | V14: TA KVFREQU | W14: NA | X14: NA | Y14: ALPHA | Z14: NA | AA14: NA | AB14: 1 | AC14: NA | AD14: 43 | AE14: NA | AF14: NA | AG14: USAGE ZP | AH14: NA | AI14: NA | AJ14: NA | AK14: NA | AL14: NA
A15: A1 | B15: 12 | C15: 00 - En-tête du flux | D15: 00 - File header | E15: A1 H.DTARRETE | F15: Date d'arrêté | G15: Closing date | H15: Date d'arrêté correspondant au contenu du fichier (norme ISO 8601) | I15: Closing date corresponding to the file's content (ISO 8601 standard) | P15: ND | Q15: ND | R15: DTARRETE | S15: Obligatoire | T15: Mandatory | U15: NA | V15: NA | W15: NA | X15: NA | Y15: DATE | Z15: AAAAMMJJ | AA15: YYYYMMDD | AB15: 8 | AC15: NA | AD15: 43 | AE15: NA | AF15: NA | AG15: USAGE ZP | AH15: NA | AI15: NA | AJ15: NA | AK15: NA | AL15: NA
A16: A1 | B16: 13 | C16: 00 - En-tête du flux | D16: 00 - File header | E16: A1 H.NUMSEQ | F16: Numéro de séquence du fichier | G16: File sequence number | H16: Permet d'identifier un lot | I16: Allows to identify a batch | P16: ND | Q16: ND | R16: NUMSEQ | S16: Obligatoire | T16: Mandatory | U16: NA | V16: NA | W16: A alimenter avec une valeur comprise entre "00001" et "99999" en fonction des lots définis par l'entité | X16: To be filled with a value between "00001" and "99999" depending of batches defined by entity | Y16: ALPHA | Z16: NA | AA16: NA | AB16: 5 | AC16: NA | AD16: 43 | AE16: NA | AF16: NA | AG16: USAGE ZP | AH16: NA | AI16: NA | AJ16: NA | AK16: NA | AL16: NA
A17: A1 | B17: 14 | C17: 00 - En-tête du flux | D17: 00 - File header | E17: A1 H.NMAPPFIN | F17: Application émettrice Finance | G17: Issuing Finance application code | H17: Code de l'application émettrice spécifique à PALMA | I17: Issuing application code specific to PALMA | P17: ND | Q17: ND | R17: NMAPPFIN | S17: Facultatif | T17: Optional | U17: NA | V17: NA | W17: Non alimenté | X17: Not filled | Y17: ALPHA | Z17: NA | AA17: NA | AB17: 5 | AC17: NA | AD17: 43 | AE17: NA | AF17: NA | AG17: USAGE ZP | AH17: NA | AI17: NA | AJ17: NA | AK17: NA | AL17: NA
A18: A1 | B18: 15 | C18: 00 - En-tête du flux | D18: 00 - File header | E18: A1 H.FILLER | F18: Filler | G18: Filler | H18: Filler pour évolutions futures | I18: Filler for future evolution | P18: ND | Q18: ND | R18: FILLER | S18: Facultatif | T18: Optional | U18: NA | V18: NA | W18: Non alimenté | X18: Not filled | Y18: ALPHA | Z18: NA | AA18: NA | AB18: =2000-(SUM(AB4:AB17)+COUNT(AB4:AB17)) -> 1886 | AC18: NA | AD18: 43 | AE18: NA | AF18: NA | AG18: NA | AH18: NA | AI18: NA | AJ18: NA | AK18: NA | AL18: NA
A19: A1 | B19: 1 | C19: 02 - Caractéristiques d'identification fonctionnelles | D19: 02 - Functional identification characteristics | E19: 0.1 (A1) | F19: Date d'arrêté | G19: Closing date | H19: Correspond à la date d'arrêté des données transmises (dernier jour calendaire du mois) | I19: Represents the cut-off date of the data transmitted (final calendar day of the month) | P19: ND | Q19: ND | R19: SttmDt | S19: Obligatoire | T19: Mandatory | U19: NA | V19: NA | W19: Il doit y avoir unicité de la date d'arrêté au sein du flux | X19: The cut-off date must be the same across the flow | Y19: ALPHA | Z19: AAAAMMJJ | AA19: YYYYMMDD | AB19: 8 | AC19: NA | AD19: 40 | AE19: NA | AF19: 45.00 | AG19: CALCULS PRUDENTIELS, LIQUIDITE | AH19: ND | AI19: N | AJ19: NA | AK19: NA | AL19: NA
A20: A1 | B20: 2 | C20: 02 - Caractéristiques d'identification fonctionnelles | D20: 02 - Functional identification characteristics | E20: 0.2 (A1) | F20: Entité Porteuse de Risques | G20: Risk taker entity | H20: Correspond au code consolidation comptable de l'Entité porteuse de risque dans les comptes de Crédit Agricole S.A. | I20: Represents the accounting consolidation code of the Entity bearing risks in the financial statements of Crédit Agricole S.A. | P20: ND | Q20: ND | R20: EntPortRisq | S20: Obligatoire | T20: Mandatory | U20: LC.0003 | V20: TA FI59 | W20: NA | X20: NA | Y20: ALPHA | Z20: NA | AA20: NA | AB20: 5 | AC20: NA | AD20: 40 | AE20: NA | AF20: 45.00 | AG20: CALCULS PRUDENTIELS, LIQUIDITE, NPE | AH20: ND | AI20: N | AJ20: NA | AK20: NA | AL20: NA | AN20: La donnée est obligatoire | AO20: The data is mandatory | AP20: 7 | AQ20: TP0001 | AR20: Si elle est renseignée, la valeur doit être connue du Langage Commun associé | AS20: If specified, the value must be known to the associated Common Language | AT20: 7 | AU20: TIG0001 | BD20: Unicité au sein de l'entité porteuse de risque | BE20: Uniqueness within the entity bearing the risk | BF20: 7 | BG20: TU0001
A21: A1 | B21: 3 | C21: 02 - Caractéristiques d'identification fonctionnelles | D21: 02 - Functional identification characteristics | E21: 0.3 (A1) | F21: Application source | G21: Source application | H21: Correspond au code du Système d'Information utilisé en local pour générer le flux En Alimentation dégradée, il faut préfixer par la lettre ‘A' le code application source | I21: Represents the code of the Information System used locally to generate the flow In Degraded data entry, the source application code must be prefix with the letter 'A' | P21: ND | Q21: ND | R21: AppliSource | S21: Obligatoire | T21: Mandatory | U21: NA | V21: TA KVAPPBK | W21: Il convient à chaque entité émettrice du flux de déterminer le(s) code(s) ‘Application source' qu'elle utilise et de le(s) porter à la connaissance de la DRG avant première utilisation dans le flux. Une fois communiqué, le code est définitif Les flux tardifs ou correctifs tardifs seront déclarés sous le code application source "CORE" imposé par la DRG | X21: Every entity issuing flows must determine what ‘Source application' code(s) it uses and inform the Group Risk Management Division thereof prior to using them in the flow. Once notified, the code can't be changed Later corrections or flows will be declared under the source application code 'CORE' imposed by DRG | Y21: ALPHA | Z21: NA | AA21: NA | AB21: 12 | AC21: NA | AD21: 40 | AE21: NA | AF21: NA | AG21: CALCULS PRUDENTIELS | AH21: ND | AI21: N | AJ21: NA | AK21: NA | AL21: NA | AN21: La donnée est obligatoire | AO21: The data is mandatory | AP21: 7 | AQ21: TP0001 | AR21: Si elle est renseignée, la valeur doit être connue du Langage Commun associé | AS21: If specified, the value must be known to the associated Common Language | AT21: 7 | AU21: TIS0067 | AV21: La donnée doit commencer par 'A' ou 'ACORE' | AW21: Data must be start with 'A' or 'ACORE' | AX21: 7 | AY21: TVS0749 | BD21: Unicité au sein de l'entité porteuse de risque | BE21: Uniqueness within the entity bearing the risk | BF21: 7 | BG21: TU0001
A22: A1 | B22: 4 | C22: 02 - Caractéristiques d'identification fonctionnelles | D22: 02 - Functional identification characteristics | E22: 0.4 (A1) | F22: Fréquence de transmission | G22: Transmission frequency | H22: Permet d'identifier le flux dans les traitements | I22: Makes it possible to identify the flow in the treatments | P22: ND | Q22: ND | R22: FreqTrans | S22: Obligatoire | T22: Mandatory | U22: NA | V22: NA | W22: 'M' pour mensuel | X22: ‘M' for monthly | Y22: ALPHA | Z22: NA | AA22: NA | AB22: 1 | AC22: NA | AD22: 40 | AE22: NA | AF22: NA | AG22: USAGE ZP | AH22: ND | AI22: N | AJ22: NA | AK22: NA | AL22: NA
A23: A1 | B23: 5 | C23: 02 - Caractéristiques d'identification fonctionnelles | D23: 02 - Functional identification characteristics | E23: 0.5 (A1) | F23: Date et Heure de traitement | G23: Date and time of processing | H23: Correspond à la date et heure du début du traitement ayant produit le flux | I23: Represents the date and time at which flow treatment began | P23: ND | Q23: ND | R23: DtHeureTrait | S23: Obligatoire | T23: Mandatory | U23: NA | V23: NA | W23: Pour un lot déterminé, la valeur de la donnée doit être unique | X23: Rule: for a given batch, the data value is unique | Y23: ALPHA | Z23: AAAAMMJJHHMM | AA23: YYYYMMDDHHMM | AB23: 12 | AC23: NA | AD23: 40 | AE23: NA | AF23: NA | AG23: USAGE ZP | AH23: ND | AI23: N | AJ23: NA | AK23: NA | AL23: NA
A24: A1 | B24: 6 | C24: 02 - Caractéristiques d'identification fonctionnelles | D24: 02 - Functional identification characteristics | E24: 0.6 (A1) | F24: Type d'enregistrement | G24: Record type | H24: Caractérise le type d'enregistrement remonté par le site | I24: Represents the record type reported by the site | P24: ND | Q24: ND | R24: TypEnreg | S24: Obligatoire | T24: Mandatory | U24: NA | V24: NA | W24: Valeur admise : 'A1' (domaine Alimentation dégradée) | X24: Permitted value: 'A1' (Degraded Data Entry section) | Y24: ALPHA | Z24: NA | AA24: NA | AB24: 2 | AC24: NA | AD24: 40 | AE24: NA | AF24: NA | AG24: USAGE ZP | AH24: ND | AI24: N | AJ24: NA | AK24: NA | AL24: NA
A25: A1 | B25: 7 | C25: 02 - Caractéristiques d'identification fonctionnelles | D25: 02 - Functional identification characteristics | E25: 0.7 (A1) | F25: Nature de flux (Zone réservée DRG) | G25: Nature of flow (Zone reserved for Group Risk Management Division) | H25: Nature de flux (Zone réservée DRG) | I25: Nature of flow (Zone reserved for Group Risk Management Division) | P25: NA | Q25: NA | R25: NatFlux | S25: NA | T25: NA | U25: NA | V25: NA | W25: (Zone réservée DRG) | X25: (Zone reserved for the Group Risk Management Division) | Y25: ALPHA | Z25: NA | AA25: NA | AB25: 1 | AC25: NA | AD25: 40 | AE25: 41 | AF25: NA | AG25: NA | AH25: NA | AI25: N | AJ25: NA | AK25: NA | AL25: NA
A26: A1 | B26: 8 | C26: 02 - Caractéristiques d'identification fonctionnelles | D26: 02 - Functional identification characteristics | E26: 0.8 (A1) | F26: Centre de Responsabilité Comptable (Zone réservée CAsa social) | G26: Accounting responsibility center (Zone reserved for Crédit Agricole S.A. Holding) | H26: Zone réservée CAsa social | I26: Zone reserved for Crédit Agricole S.A. | P26: ND | Q26: ND | R26: ZoneResCasa | S26: Obligatoire sous conditions | T26: Mandatory under conditions | U26: LC.0072 | V26: TA KVCRC | W26: Zone exploitée uniquement par les entités déclarant les risques portés par Crédit Agricole S.A. Décomposition comptable du Siège en Activités (comptabilités auxiliaires). Permet de gérer les opérations pour compte propre Casa | X26: Zone only used for entities reporting risks borne by Crédit Agricole S.A. Accounting breakdown of HQ into Activities (sub-ledgers). Makes it possible to manage Crédit Agricole S.A. proprietary trading | Y26: ALPHA | Z26: NA | AA26: NA | AB26: 2 | AC26: NA | AD26: 40 | AE26: NA | AF26: 45.00 | AG26: CALCULS PRUDENTIELS, LIQUIDITE, NPE | AH26: ND | AI26: N | AJ26: NA | AK26: NA | AL26: NA | AN26: La donnée est obligatoire, si Entité Porteuse de Risques [0.2 (A1)] = '00018' | AO26: The data is mandatory if Entity Id [0.2 (A1)] = '00018' | AP26: 7 | AQ26: TPS1782 | AR26: Si elle est renseignée, la valeur doit être connue du Langage Commun associé | AS26: If specified, the value must be known to the associated Common Language | AT26: 7 | AU26: TIG0001
A27: A1 | B27: 9 | C27: 02 - Caractéristiques d'identification fonctionnelles | D27: 02 - Functional identification characteristics | E27: 0.99 (A1) | F27: Zone Libre | G27: Free zone | H27: Zone Libre | I27: Free zone | P27: NA | Q27: NA | R27: ZoneLibre0 | S27: NA | T27: NA | U27: NA | V27: NA | W27: NA | X27: NA | Y27: ALPHA | Z27: NA | AA27: NA | AB27: 7 | AC27: NA | AD27: 40 | AE27: 41 | AF27: NA | AG27: NA | AH27: NA | AI27: N | AJ27: NA | AK27: NA | AL27: NA
A28: A1 | B28: 10 | C28: 02 - Caractéristiques d'identification fonctionnelles | D28: 02 - Functional identification characteristics | E28: A1 1.98 | F28: Zone réservée DRG | G28: Zone reserved for the Group Risk Management Division | H28: Zone réservée DRG | I28: Zone reserved for the Group Risk Management Division | P28: NA | Q28: NA | R28: ZoneResDRG1 | S28: NA | T28: NA | U28: NA | V28: NA | W28: (Zone réservée DRG) | X28: (Zone reserved for the Group Risk Management Division) | Y28: ALPHA | Z28: NA | AA28: NA | AB28: 130 | AC28: NA | AD28: 40 | AE28: 41 | AF28: NA | AG28: NA | AH28: NA | AI28: N | AJ28: NA | AK28: NA | AL28: NA
A29: A1 | B29: 11 | C29: 02a - Caractéristiques d'identification fonctionnelles (clé) | D29: 02a - Functional identification characteristics (key) | E29: A1 1.11 | F29: Identifiant de l'engagement | G29: Product identifier | H29: Identifiant unique dans le système local utilisé pour générer le flux | I29: Unique ID in the local system used to generate the flow | P29: ND | Q29: ND | R29: IdEng | S29: Obligatoire | T29: Mandatory | U29: NA | V29: NA | W29: Pour un lot déterminé, l'identifiant doit être unique au sein du lot | X29: For a given batch, the ID must be unique within the batch | Y29: ALPHA | Z29: NA | AA29: NA | AB29: 40 | AC29: NA | AD29: 40 | AE29: NA | AF29: 45.00 | AG29: CALCULS PRUDENTIELS, LIQUIDITE, NPE | AH29: ND | AI29: N | AJ29: NA | AK29: NA | AL29: NA | AN29: La donnée est obligatoire | AO29: The data is mandatory | AP29: 7 | AQ29: TP0001 | BD29: L'identifiant renseigné doit être unique au sein de l'entité porteuse de risque | BE29: The identifier provided must be unique within the entity carrying the risk | BF29: 7 | BG29: TU0001
A30: A1 | B30: 12 | C30: 02 - Caractéristiques d'identification fonctionnelles | D30: 02 - Functional identification characteristics | E30: A1 1.99 | F30: Zone réservée DRG | G30: Zone reserved for the Group Risk Management Division | H30: Zone réservée DRG | I30: Zone reserved for the Group Risk Management Division | P30: NA | Q30: NA | R30: ZoneResDRG2 | S30: NA | T30: NA | U30: NA | V30: NA | W30: (Zone réservée DRG) | X30: (Zone reserved for the Group Risk Management Division) | Y30: ALPHA | Z30: NA | AA30: NA | AB30: 60 | AC30: NA | AD30: 40 | AE30: 41 | AF30: NA | AG30: NA | AH30: NA | AI30: N | AJ30: NA | AK30: NA | AL30: NA
A31: A1 | B31: 13 | C31: 16 - Identification Tiers | D31: 16 - Third party identification | E31: A1 2.1 | F31: CAP de l'exposition | G31: CAP of exposure | H31: Le champ correspond à la Classe d'Actif de Pondération de l'encours (contrepartie, émetteur des titres ou autres) | I31: The field represents the Asset class for weighting purposes of the outstanding amount (counterparty, issuer of securities or other) | P31: ND | Q31: ND | R31: cdCapExpo | S31: Obligatoire | T31: Mandatory | U31: LC.0084 | V31: TA H8CAP | W31: Les valeurs autorisées en méthode Standard : - actions et assimilés : CAP = 14 - titrisation : CAP = 15 - titres hors actions, la CAP correspond à l'émetteur du titre - expositions sur la Clientèle de détail, la CAP correspond au type d'engagement ou à la typologie de la contrepartie - autres types d'engagement, la CAP correspond à la contrepartie | X31: Values autorised for Standard approach: - For equities and equivalent: CAP = 14 - For securitisation: CAP = 15 - For securities excluding equities, the CAP represents the issuer of the security - For exposures vis-à-vis retail banking customers, the CAP represents the type of commitment or the type of counterparty - For other commitment types, the CAP represents the counterparty | Y31: ALPHA | Z31: NA | AA31: NA | AB31: 12 | AC31: NA | AD31: 40 | AE31: NA | AF31: NA | AG31: CALCULS PRUDENTIELS, ESG PILIER 3 | AH31: ND | AI31: N | AJ31: NA | AK31: NA | AL31: NA | AN31: La donnée est obligatoire | AO31: The data is mandatory | AP31: 7 | AQ31: TPG0001 | AR31: Si elle est renseignée, la valeur doit être connue du Langage Commun associé | AS31: If specified, the value must be known to the associated Common Language | AT31: 7 | AU31: TIG0001 | AV31: Si Méthodologie Bâloise [A1 3.2] = 'NA330', alors la donnée doit être égale à ('14', '60') | AW31: If Basel methodology [A1 3.2] = 'NA330', then data must be equal to ('14', '60') | AX31: 6 | AY31: TVS0766
A32: A1 | B32: 14 | C32: 16 - Identification Tiers | D32: 16 - Third party identification | E32: A1 2.2 | F32: État - pays de résidence fiscal | G32: Sovereign - country of fiscal residence | H32: Le champ correspond au pays de résidence fiscal de la contrepartie / de l'émetteur des titres | I32: The field is for the country of fiscal residence of the counterparty / issuer of securities | P32: ND | Q32: ND | R32: cdPaysFisc | S32: Obligatoire | T32: Mandatory | U32: LC.0004 LC.0273 | V32: TA NM252 (pour la partie ISO 3166) TA NM258 (organisation supra nationales) | W32: NA | X32: NA | Y32: ALPHA | Z32: NA | AA32: NA | AB32: 2 | AC32: NA | AD32: 40 | AE32: NA | AF32: NA | AG32: CALCULS PRUDENTIELS, ESG PILIER 3 | AH32: ND | AI32: N | AJ32: NA | AK32: NA | AL32: NA | AN32: La donnée est obligatoire | AO32: The data is mandatory | AP32: 7 | AQ32: TPG0001 | AR32: Si elle est renseignée, la valeur doit être connue du Langage Commun associé | AS32: If specified, the value must be known to the associated Common Language | AT32: 7 | AU32: TIG0001
A33: A1 | B33: 15 | C33: 16 - Identification Tiers | D33: 16 - Third party identification | E33: A1 2.3 | F33: Indicateur Contrepartie/Emetteur - Traitement spécifique | G33: Counterparty / Issuer indicator - specific treatment | H33: Le champ permet d'identifier les contreparties/émetteur de titres ayant un traitement spécifique | I33: The field makes it possible to identify the counterparties / issuer of securities subject to special treatment | P33: ND | Q33: ND | R33: idCtpTraitSpe | S33: Facultatif | T33: Optional | U33: LC.0146 | V33: TA KVCPPREF | W33: NA | X33: NA | Y33: ALPHA | Z33: NA | AA33: NA | AB33: 2 | AC33: NA | AD33: 40 | AE33: NA | AF33: NA | AG33: CALCULS PRUDENTIELS | AH33: ND | AI33: N | AJ33: NA | AK33: NA | AL33: NA | AR33: Si elle est renseignée, la valeur doit être connue du Langage Commun associé | AS33: If specified, the value must be known to the associated Common Language | AT33: 7 | AU33: TIG0001
A34: A1 | B34: 16 | C34: 16 - Identification Tiers | D34: 16 - Third party identification | E34: A1 2.4 | F34: Code partenaire de la contrepartie en risque | G34: Partner code of the counterparty at-risk | H34: Le champ permet de distinguer les opérations intragroupes et hors-groupe | I34: The field makes it possible to distinguish between inter-company and non-group transactions | P34: ND | Q34: ND | R34: cdPartCtp | S34: Obligatoire | T34: Mandatory | U34: LC.0003 | V34: TA FI59 RB NM281 | W34: Il s'agit du code de consolidation de l'entité partenaire dans le cas d'une opération intragroupe ou à un code générique dans le cas d'une opération hors-groupe Liste des codes partenaire : - '99999' s'il s'agit d'une entité Hors Groupe | X34: This is the consolidation code of the partner entity in the case of an inter-company transaction or a generic code in the case of a non-group transaction List of partner codes: - '99999' where it involves a Non-Group entity | Y34: NUM | Z34: NA | AA34: NA | AB34: 5 | AC34: NA | AD34: 40 | AE34: NA | AF34: 45.00 | AG34: CALCULS PRUDENTIELS, ESG PILIER 3, LIQUIDITE | AH34: ND | AI34: N | AJ34: NA | AK34: NA | AL34: NA | AN34: La donnée est obligatoire | AO34: The data is mandatory | AP34: 7 | AQ34: TPG0001 | AR34: Si elle est renseignée, la valeur doit être connue du Langage Commun associé | AS34: If specified, the value must be known to the associated Common Language | AT34: 7 | AU34: TIG0001
A35: A1 | B35: 17 | C35: 16 - Identification Tiers | D35: 16 - Third party identification | E35: A1 2.5 | F35: Echelon de qualité de crédit de la Contrepartie/Emetteur | G35: Issuer/ Counterparty credit quality level | H35: Echelon de qualité de crédit de la Contrepartie/Emetteur | I35: Issuer/ Counterparty credit quality level | P35: ND | Q35: ND | R35: cdEchelQualCreCtp | S35: Facultatif | T35: Optional | U35: LC.0178 | V35: TA KVECHLON | W35: NA | X35: NA | Y35: ALPHA | Z35: NA | AA35: NA | AB35: 1 | AC35: NA | AD35: 40 | AE35: NA | AF35: NA | AG35: CALCULS PRUDENTIELS | AH35: ND | AI35: N | AJ35: NA | AK35: NA | AL35: NA | AR35: Si elle est renseignée, la valeur doit être connue du Langage Commun associé | AS35: If specified, the value must be known to the associated Common Language | AT35: 7 | AU35: TIG0001
A36: A1 | B36: 18 | C36: 16 - Identification Tiers | D36: 16 - Third party identification | E36: A1 2.6 | F36: Code ISIN pour les opérations sur titres | G36: ISIN code for securities transactions | H36: Le code ISIN (International Securities Identification Numbers) est un identifiant unique, propre à chaque actif financier (actions, obligations, produits monétaires, OPCVM, warrants...) Le code ISIN est composé de deux lettres indiquant le pays d'émission du titre (FR pour la France) et de dix chiffres propres à chaque titre | I36: The ISIN code (International Securities Identification Numbers) is a single ID, peculiar to each financial asset (share, bond, currency product, UCITS, warrants, etc.) The ISIN code includes two letters for the country (FR for France) and ten figures peculiar to each security | P36: ND | Q36: ND | R36: cdISIN | S36: Obligatoire sous conditions | T36: Mandatory under conditions | U36: NA | V36: NA | W36: Toutes les opérations sur titres (titre détenu, repo, reverse, prêts, emprunts, OPCVM, …) doivent être remontées à une maille granulaire par code ISIN | X36: All securities transactions (securities held, repo, reverse, loans, borrowings, UCITS, etc.) must be traced back to a granular mesh by ISIN code | Y36: ALPHA | Z36: NA | AA36: NA | AB36: 12 | AC36: NA | AD36: 40 | AE36: NA | AF36: 45.00 | AG36: CALCULS PRUDENTIELS, ESG PILIER 3, LIQUIDITE | AH36: ND | AI36: N | AJ36: NA | AK36: NA | AL36: NA | AN36: La donnée est obligatoire, si Type de produit bancaire [A1 3.7] = 'EMTI01, PRTI01, REPO01, RREP01, TDET*' | AO36: The data is mandatory, if Banking Product type [A1 3.7] = 'EMTI01, PRTI01, REPO01, RREP01, TDET*' | AP36: 7 | AQ36: TBD | AV36: Si la donnée est renseignée, alors la donnée doit commencer par 2 caractères alphabétiques et avoir une longueur de 12 caractères avec un caractère numérique pour le dernier caractère ET la donnée doit être validée comme un code ISIN à l'aide de l'algorithme de Luhn | AW36: If filled, then the data must start with 2 alphabetic characters and have a length of 12 characters with a numeric character for the last character AND the data must be validated as an ISIN code using the Luhn algorithm | AX36: 6 | AY36: TVG0006
A37: A1 | B37: 19 | C37: 16 - Identification Tiers | D37: 16 - Third party identification | E37: A1 2.7 | F37: Nombre de contreparties | G37: Number of counterparties | H37: Nombre de contreparties constituant l'encours dégradé | I37: Number of counterparties which forms the degraded outstanding | P37: ND | Q37: ND | R37: nbCtp | S37: Facultatif | T37: Optional | U37: NA | V37: NA | W37: Il s'agit du nombre de contreparties constituant l'encours dégradé | X37: Number of counterparties which forms the degraded outstanding | Y37: ALPHA | Z37: NA | AA37: NA | AB37: 8 | AC37: NA | AD37: 40 | AE37: NA | AF37: NA | AG37: CALCULS PRUDENTIELS | AH37: ND | AI37: N | AJ37: NA | AK37: NA | AL37: NA
A38: A1 | B38: 20 | C38: 16 - Identification Tiers | D38: 16 - Third party identification | E38: A1 2.99 | F38: Zone libre | G38: Free zone | H38: Zone libre | I38: Free zone | P38: NA | Q38: NA | R38: ZoneLibre2 | S38: NA | T38: NA | U38: NA | V38: NA | W38: NA | X38: NA | Y38: ALPHA | Z38: NA | AA38: NA | AB38: 30 | AC38: NA | AD38: 40 | AE38: 41 | AF38: NA | AG38: NA | AH38: NA | AI38: N | AJ38: NA | AK38: NA | AL38: NA
A39: A1 | B39: 21 | C39: 03 - Caractéristiques Générales | D39: 03 - General characteristics | E39: A1 3.1 | F39: Méthodologie Bâloise | G39: Basel methodology | H39: Correspond à la méthode de calcul des risques pondérés dans Bâle | I39: Represents the risk-weighted asset calculation method in Basel | P39: ND | Q39: ND | R39: cdMetBal | S39: Obligatoire | T39: Mandatory | U39: LC.0068 | V39: TA KVBAL22 | W39: La seule valeur autorisée est : - STD (STANDARD) | X39: The only permitted value is: - STD (STANDARDISED) | Y39: ALPHA | Z39: NA | AA39: NA | AB39: 7 | AC39: NA | AD39: 40 | AE39: NA | AF39: NA | AG39: CALCULS PRUDENTIELS, ESG PILIER 3, NPE | AH39: ND | AI39: N | AJ39: NA | AK39: NA | AL39: NA | AN39: La donnée est obligatoire | AO39: The data is mandatory | AP39: 7 | AQ39: TPG0001 | AR39: Si elle est renseignée, la valeur doit être connue du Langage Commun associé | AS39: If specified, the value must be known to the associated Common Language | AT39: 7 | AU39: TIG0001 | AV39: Si renseignée, la donnée doit être égale à 'STD' | AW39: If filled, data must be equal to 'STD' | AX39: 7 | AY39: TVS0750
A40: A1 | B40: 22 | C40: 03 - Caractéristiques Générales | D40: 03 - General characteristics | E40: A1 3.5 | F40: Traitement moteur bâlois | G40: Basel engine treatment | H40: Correspond au traitement moteur de calcul des RWA Bâlois | I40: Represents treatment by the Basel RWA calculation engine | P40: ND | Q40: ND | R40: cdTraitMot | S40: Obligatoire | T40: Mandatory | U40: LC.0154 | V40: TA KVTBALE | W40: NA | X40: NA | Y40: ALPHA | Z40: NA | AA40: NA | AB40: 2 | AC40: NA | AD40: 40 | AE40: NA | AF40: NA | AG40: CALCULS PRUDENTIELS | AH40: ND | AI40: N | AJ40: NA | AK40: NA | AL40: NA | AN40: La donnée est obligatoire | AO40: The data is mandatory | AP40: 7 | AQ40: TPG0001 | AR40: Si elle est renseignée, la valeur doit être connue du Langage Commun associé | AS40: If specified, the value must be known to the associated Common Language | AT40: 7 | AU40: TIG0001 | AV40: Si renseignée, la donnée doit être égale à '01' (réglementaire) ou '07' (simulation) | AW40: If filled, data must be equal to '01' (regulatory) or '07' (simulation) | AX40: 7 | AY40: TVS0751
...

Sheet Ctrl cohérence-consistency ctr 
B2: Contrôles de cohérence | L2: Consistency controls
B4: Principe : Ces contrôles consistent à vérifier que la valeur portée par une donnée pivot est cohérente avec des données associées. Un contrôle de cohérence peut porter sur : · Une ou plusieurs données d’un même objet de collecte · Plusieurs données de plusieurs objets de collecte | L4: Principle: These controls are to ensure that the value of a pivot data is consistent with associated data. A consistency check may cover: ・ One or more data from the same data collection object ・ Several data from several data collection objects
B6: Périmètre d'application : - CRR Corporate - CRR Retail Agrégé - CRR Adapté | L6: Scope of application: - CRR Corporate - CRR Aggregated Retail - Adapted CRR
B8: Fonctionnement : - Contrôles exécutés en étape E4.4 des traitements ZP (après mise au modèle) - Contrôles paramétrés en score 6TA (non bloquant) - Les combinaisons de valeurs conformes sont précisées ci-dessous pour chaque contrôle sauf contrôle TC0C03 pour lequel sont précisées les combinaisons en anomalie. En dehors des combinaisons conformes, la Zone de Partage recensera une anomalie. | L8: Functions: - Checks performed in step E4.4 of ZP treatments (after the model has been set) - Controls configured in scoring 6TA (non-blocking) - The combinations of conforming values are specified below for each control except control TC0C03 for which the combinations in anomaly are specified. Apart from the compliant combinations, the Sharing Zone will identify an anomaly.
B10: Légende : | L10: Legend:
B11: * : Quelle que soit la valeur | L11: * Whatever the value
B12: Donnée pivot | L12: Pivot data
B13: Donnée complémentaire | L13: Additional data
B19: Contrôle TC0C11 : Cohérence NATO/Domaine CRR | L19: Control TC0C11 : NATO/CRR domain consistency
B20: Description du contrôle | D20: Périmètre | L20: Description of control | N20: Scope
B21: Ce contrôle consiste à vérifier l’utilisation de la NATO avec les domaines du CRR pour chacun des flux CRR transmis | D21: Grande Clientèle, Clientèle de détail et Alimentation adaptée | L21: This control consists in checking the use of the NATO with the CRR domains for each of the CRR flows transmitted | N21: Corporate customers, Retail customers and Adapted food
B24: A1 | L24: A1
C26: Nature d'Opération (A1 3.2, A1 6.5) | D26: Objet de collecte | M26: NATure of funds in use transaction (A1 3.2, A1 6.5) | N26: Business object
B27: A1 3.2 | C27: NA011, NA012, NA021, NA022, NA311, NA312, NA321, NA322, NA323, NA330, NA341, NA342, NA343, NA344, NA350, NA361, NA362, NA363, NA364, NA365, NA366, NA367, NA368, NA369, NA370, NA371, NAT41, NAT42, NAT43, NAT44, NAT06, NAT07, NA101, NA102 | D27: A1 | L27: A1 3.2 | M27: NA011, NA012, NA021, NA022, NA311, NA312, NA321, NA322, NA323, NA330, NA341, NA342, NA343, NA344, NA350, NA361, NA362, NA363, NA364, NA365, NA366, NA367, NA368, NA369, NA370, NA371, NAT41, NAT42, NAT43, NAT44, NAT06, NAT07, NA101, NA102 | N27: A1
B28: A1 6.5 | C28: NAT81, NAT82, NAT83, NAT84, NAT85 | D28: A1 | L28: A1 6.5 | M28: NAT81, NAT82, NAT83, NAT84, NAT85 | N28: A1
B33: Contrôle TC0C16 : Cohérence Crédit-bail | L33: Control TC0C16 : Credit-lease consistency
B34: Description du contrôle | D34: Périmètre | L34: Description of control | N34: Scope
B35: Le contrôle consiste à s’assurer que la saisie de certains champs a bien été effectuée pour les expositions du portefeuille CREDIT BAIL | D35: Grande Clientèle, Clientèle de détail et Standard en Alimentation adaptée | L35: The control consists in ensuring that certain fields have been entered for exposures of the CREDIT BAIL portfolio | N35: Corporate customers, Retail Customers and Standard in Adapted Feeding
B37: A1 | L37: A1
B39: Achat en fin de contrat du bien loué (A1 5.4) | C39: Usage du bien immobilier apporté en garantie (A1 5.1) | D39: Valeur estimée en fin de période du bien loué (A1 5.5) | E39: Devise de la valeur estimée en fin de période du bien loué (A1 3.3) | F39: Valeur hypothécaire du bien immobilier loué à la date d'évaluation (A1 5.3) | G39: Devise de la valeur hypothécaire du bien immobilier loué à la date d'évaluation (A1 3.3) | H39: Valeur de marché du bien immobilier loué à la date d'évaluation (A1 5.2) | I39: Devise de la valeur de marché du bien immobilier loué à la date d'évaluation (A1 3.3) | L39: Purchase at the end of the lease of the leased property (A1 5.4) | M39: Use of real estate (A1 5.1) | N39: Estimated value at the end of the period of the leased property (A1 5.5) | O39: Currency of the estimated value at the end of the period of the leased property (A1 3.3) | P39: Mortgage value of leased real estate at valuation date (A1 5.3) | Q39: Currency of the mortgage value of the leased property at the valuation date (A1 3.3) | R39: Market value|fair value of leased real estate at the latest valuation date (A1 5.2) | S39: Currency of the market value|fair value of the leased property on the valuation date (A1 3.3)
B40: 1 | C40: 1 | D40: ≠ 0 | E40: (Non vide) | F40: ≠ 0 | G40: (Non vide) | H40: ≠ 0 | I40: (Non vide) | L40: 1 | M40: 1 | N40: ≠ 0 | O40: (Non vide) | P40: ≠ 0 | Q40: (Non vide) | R40: ≠ 0 | S40: (Non vide)
B41: 2 | C41: 1 | D41: * | E41: * | F41: ≠ 0 | G41: (Non vide) | H41: ≠ 0 | I41: (Non vide) | L41: 2 | M41: 1 | N41: * | O41: * | P41: ≠ 0 | Q41: (Non vide) | R41: ≠ 0 | S41: (Non vide)
B42: 1 | C42: 2 | D42: ≠ 0 | E42: (Non vide) | F42: * | G42: * | H42: ≠ 0 | I42: (Non vide) | L42: 1 | M42: 2 | N42: ≠ 0 | O42: (Non vide) | P42: * | Q42: * | R42: ≠ 0 | S42: (Non vide)
B43: 2 | C43: 2 | D43: * | E43: * | F43: * | G43: * | H43: ≠ 0 | I43: (Non vide) | L43: 2 | M43: 2 | N43: * | O43: * | P43: * | Q43: * | R43: ≠ 0 | S43: (Non vide)
B44: 1 | C44: ≠ 1 et ≠ 2 | D44: ≠ 0 | E44: (Non vide) | F44: * | G44: * | H44: * | I44: * | L44: 1 | M44: ≠ 1 et ≠ 2 | N44: ≠ 0 | O44: (Non vide) | P44: * | Q44: * | R44: * | S44: *
B50: Contrôle TC0C26 : Cohérence NATO/Engagement douteux en STD | L50: Control TC0C26 : NATO/doubtful Funds in use consistency in STD
B51: Description du contrôle | D51: Périmètre | L51: Description of control | N51: Scope
B52: Le contrôle consiste à vérifier que la NATure d’Opération dans laquelle l’encours a été classé est cohérente avec le caractère douteux/non douteux de l’encours traité en méthode Standard STD | D52: Grande Clientèle, Clientèle de détail et Alimentation adaptée, en méthode Standard | L52: The control consists in checking that the NATure of the operation in which the outstanding has been classified is consistent with the doubtful/undoubted nature of the outstanding treated in the STD standard method | N52: Corporate customers, Retail customers and appropriate food, using the Standard method
B54: A1 | L54: A1
B56: NATO de l'exposition (A1 3.2) | C56: Indicateur 'Engagement Douteux' (A1 4.14) | L56: NATO of the exhibition (A1 3.2) | M56: 'Doubtful Funds in use' indicator (A1 4.14)
B57: NA011, NA021, NA101 | C57: N | L57: NA011, NA021, NA101 | M57: N
B58: NA012, NA022, NA102 | C58: Y | L58: NA012, NA022, NA102 | M58: Y
