Workbook
Name aaaa: #REF!
Name aaaa: #REF!
Name aaaaa: #REF!
Name aaaaa: #REF!
Name anomalies: #REF!
Name anomalies: #REF!
Name CAP_01__02__03__04__Clientèle_de_détail___Pas_de_données_complémentaires_obligatoires_associées_à_ces_CAP__Les_expositions_sur_la_Clientèle_de_détail_sont_pondérées_à_75_.: #REF!
Name CAP_01__02__03__04__Clientèle_de_détail___Pas_de_données_complémentaires_obligatoires_associées_à_ces_CAP__Les_expositions_sur_la_Clientèle_de_détail_sont_pondérées_à_75_.: #REF!
Name CAP_de_l_exposition: #REF!
Name CAP_de_l_exposition: #REF!
Name CAPtest: '[1]A1 Degraded Data Entry'!#REF!
Name CAPtest: '[1]A1 Degraded Data Entry'!#REF!
Name Groupe_caractéristiques: #REF!
Name Groupe_caractéristiques: #REF!
Name Méthodo_CAP: #REF!
Name Méthodo_CAP: #REF!
Name Méthodo_Conditions_réglementaires: #REF!
Name Méthodo_Conditions_réglementaires: #REF!
Name Méthodo_Crédit_bail: #REF!
Name Méthodo_Crédit_bail: #REF!
Name Méthodo_DeterminationCAP: #REF!
Name Méthodo_DeterminationCAP: #REF!
Name Méthodo_douteux_impayé: #REF!
Name Méthodo_douteux_impayé: #REF!
Name Méthodo_engagement: #REF!
Name Méthodo_engagement: #REF!
Name Méthodo_impayé: #REF!
Name Méthodo_impayé: #REF!
Name Méthodo_indicateur: #REF!
Name Méthodo_indicateur: #REF!
Name Méthodo_indicateur_couverture: [2]Méthodologie!#REF!
Name Méthodo_indicateur_couverture: #REF!
Name Méthodo_Montants: #REF!
Name Méthodo_Montants: #REF!
Name Méthodo_NATO: #REF!
Name Méthodo_NATO: #REF!
Name Méthodo_PNU: #REF!
Name Méthodo_PNU: #REF!
Name Méthodo_Pond_pref: #REF!
Name Méthodo_Pond_pref: #REF!
Name méthodo_provisions: #REF!
Name Méthodo_provisions: #REF!
Name Méthodo_sûretés: #REF!
Name Méthodo_sûretés: #REF!
Name Méthodo_Tiers_Agrégat: #REF!
Name Méthodo_Tiers_Agrégat: #REF!
Name Méthodo_usage_bien_immo: #REF!
Name Méthodo_usage_bien_immo: #REF!
Name Objets: '[3]Liste des objets'!$A:$A
Name Règles_corr: #REF!
Name Règles_corr: #REF!
Name test: #REF!
Name test: #REF!
Name Tiers_Agrégat: #REF!
Name Tiers_Agrégat: #REF!
Name Toto: #REF!
Name Toto: #REF!

Sheet Modifications
A1: Modifications
H2: Nombre de contrôles par type et sévérité
A3: Emetteur / Issuer | C3: Crédit Agricole SA : Programme Convergence Finances Risques (Crédit Agricole SA/FIG/DOP/CFR) | H3: 7 | I3: 6 | J3: 5 | K3: Mix | L3: total
A4: Date de diffusion / Publication date | C4: Lorsque cette date est renseignée, cela signifie que la notice est publiée dans https://service.ca-mocca.com/maia-collab/CFR/SitePages/Notices.aspx qui reprend l'ensemble des versions publiées. | G4: Présence | H4: =COUNTIF('PACT Corp'!$AJ$4:$AJ$1504,Modifications!H$3) -> 328 | I4: =COUNTIF('PACT Corp'!$AJ$4:$AJ$1504,Modifications!I$3) -> 460 | J4: =COUNTIF('PACT Corp'!$AJ$4:$AJ$1504,Modifications!J$3) -> 59 | K4: =L4-SUM(H4:J4) -> 5 | L4: =COUNTA('PACT Corp'!$AJ$4:$AJ$1504) -> 852
C5: You can find all the published versions on https://service.ca-mocca.com/maia-collab/CFR/SitePages/Notices_EN.aspx | G5: Référentiel | H5: =COUNTIF('PACT Corp'!$AN$4:$AN$1504,Modifications!H$3) -> 615 | I5: =COUNTIF('PACT Corp'!$AN$4:$AN$1504,Modifications!I$3) -> 0 | J5: =COUNTIF('PACT Corp'!$AN$4:$AN$1504,Modifications!J$3) -> 0 | K5: =L5-SUM(H5:J5) -> 0 | L5: =COUNTA('PACT Corp'!$AN$4:$AN$1504) -> 615
A6: Descriptif de la Mise à jour / Modifications | C6: Descriptif de la modification / Modification description | G6: Valeur | H6: =COUNTIF('PACT Corp'!$AR$4:$AR$1504,Modifications!H$3) -> 205 | I6: =COUNTIF('PACT Corp'!$AR$4:$AR$1504,Modifications!I$3) -> 18 | J6: =COUNTIF('PACT Corp'!$AR$4:$AR$1504,Modifications!J$3) -> 0 | K6: =L6-SUM(H6:J6) -> 4 | L6: =COUNTA('PACT Corp'!$AR$4:$AR$1504) -> 227
A7: Couleur / Color | C7: Permet d'identifier les zones ajoutées/modifiées | G7: Intra-objet | H7: =COUNTIF('PACT Corp'!$AV$4:$AV$1504,Modifications!H$3) -> 28 | I7: =COUNTIF('PACT Corp'!$AV$4:$AV$1504,Modifications!I$3) -> 58 | J7: =COUNTIF('PACT Corp'!$AV$4:$AV$1504,Modifications!J$3) -> 0 | K7: =L7-SUM(H7:J7) -> 0 | L7: =COUNTA('PACT Corp'!$AV$4:$AV$1504) -> 86
C8: The color code enables identification of the different kinds of evolutions | G8: Inter-objet | H8: =COUNTIF('PACT Corp'!$AZ$4:$AZ$1504,Modifications!H$3) -> 34 | I8: =COUNTIF('PACT Corp'!$AZ$4:$AZ$1504,Modifications!I$3) -> 18 | J8: =COUNTIF('PACT Corp'!$AZ$4:$AZ$1504,Modifications!J$3) -> 0 | K8: =L8-SUM(H8:J8) -> 23 | L8: =COUNTA('PACT Corp'!$AZ$4:$AZ$1504) -> 75
G9: Cohérence | H9: =COUNTIF('PACT Corp'!$BD$4:$BD$1504,Modifications!H$3) -> 0 | I9: =COUNTIF('PACT Corp'!$BD$4:$BD$1504,Modifications!I$3) -> 20 | J9: =COUNTIF('PACT Corp'!$BD$4:$BD$1504,Modifications!J$3) -> 0 | K9: =L9-SUM(H9:J9) -> 0 | L9: =COUNTA('PACT Corp'!$BD$4:$BD$1504) -> 20
A12: Suivi des versions / Version tracking
A13: Date de diffusion / Publication date | B13: Publication mocca n° | C13: Descriptif de la mise à jour / Modifications | D13: Couleur / Color
A14: 46014 | B14: 45.00 | C14: Ajout de nouvelles données / New data addition
A15: 46014 | B15: 45.00 | C15: Ajouter des séparateurs ';' entre chaque donnée / Semicolon ';' to be added between each data
A16: 46014 | B16: 45.00 | C16: Modifications / Modifications Changement de longueur en passant de 5 à 50 caractères sur P1 21.65 / Length change from 5 to 50 characters on P1 21.65
A17: 46149 | B17: 45.01 | C17: Modifications mineures / Minor modifications Ajustement d'un libéllé de contrôle, ajout des codes contrôles, ajustement de la liste des usages déclarés, ajustement du périmètre de collecte / Control name update, control codes addition, declared usages update, collection scope update
A18: 46149 | B18: 45.01 | C18: Modifications majeures / Major modifications Ajout d'une donnée, modification de contrôle, suppression de contrôle, désactivation de données, / Data addition, Control update or deletion, data deactivation
A19: 46220 | B19: 45.02 | C19: Modifications majeures / Major modifications Modification de définitions, règles de gestion et contrôles pour les données P1 621 et P1 622/ Modification of definitions, management rules and controls for P1 621 and P1 622 data items
A20: 46220 | B20: 45.02 | C20: Modifications mineures / Minor modifications Retrait de l'usage CALCULS PRUDENTIELS des donnée P1 30.x, Ajustement du périmètre de collecte / Removal of CALCULS PRUDENTIELS usage the from the P1 30.X data items, correction of collection scope
A22: Liens utiles / Useful Links
A23: Langages Communs / Common Languages | C23: https://service.ca-mocca.com/maia-collab/CFR/SitePages/Langages_Communs.aspx https://service.ca-mocca.com/maia-collab/CFR/SitePages/Common_Languages.aspx
A24: Manuel des Echanges Entités-Zone de Partage et Notices / Exchange Manual ZP-entities and Notices | C24: https://service.ca-mocca.com/maia-collab/CFR/SitePages/Notices.aspx https://service.ca-mocca.com/maia-collab/CFR/SitePages/Notices_EN.aspx
A25: Guide Méthodologique - Alimentation PACT (ex CRR) / Methodological Guide - PACT (ex CRR) Feeding | C25: https://service.ca-mocca.com/maia-collab/CFR/SitePages/Notices.aspx https://service.ca-mocca.com/maia-collab/CFR/SitePages/Notices_EN.aspx

Sheet PACT Corp
AH1: CTRL PRESENCE / PRESENCE CTRL | AL1: CTRL REFERENTIEL / REFERENTIEL CTRL | AP1: CTRL VALEUR / VALUE CTRL | AT1: CTRL INTRA-OBJET / INTRA-OBJECT CTRL | AX1: CTRL INTER-OBJET / INTER-OBJECT CTRL | BB1: CTRL COHERENCE (cf. onglet dédié) / CONSISTENCY CTRL (cf. dedicated tab)
A2: OBJET DE COLLECTE / COLLECTION OBJECT | B2: N° D'ORDRE TECHNIQUE DE LA DONNEE / TECHNICAL ORDER NUMBER OF THE DATA IN THE FILE | C2: BLOC DE DONNEES | D2: DATA BLOCK | E2: REFERENCE DE COLLECTE / COLLECTION REFERENCE | F2: NOM DE LA DONNEE | G2: DATA NAME | H2: DEFINITION | I2: DEFINITION | J2: TERME METIER | K2: BUSINESS TERM | L2: CODE TECHNIQUE / TECHNICAL CODE | M2: EXIGENCE D'ALIMENTATION | N2: SUPPLY REQUIREMENT | O2: REFERENCE DE LANGAGE COMMUN / COMMON LANGUAGE REFERENCE | P2: TABLE START / START Table | Q2: REGLE DE GESTION | R2: MANAGEMENT RULE | S2: FORMAT | T2: REGLE DE FORMATAGE | U2: FORMATTING RULE | V2: LONGUEUR / LENGTH | W2: POSITION / POSITION | X2: VERSION DE CREATION / FIRST APPEARANCE VERSION | Y2: VERSION DE DERNIERE APPARITION / LAST APPEARANCE VERSION | Z2: VERSION DE MODIFICATION / MODIFICATION VERSION | AA2: USAGE(S) DECLARE(S) / DECLARED USAGE | AB2: DONNEE CRITIQUE POUR / CRITICAL DATA FOR | AC2: DONNEE A CARACTERE PERSONNEL / PERSONNAL DATA | AD2: PERIMETRE DE COLLECTE / COLLECTION SCOPE | AE2: APPLICATION REMETTANTE / REMITTING APPLICATION | AF2: REFERENCE DE LA DONNEE DANS L'APPLICATION REMETTANTE / DATA REFERENCE IN REMITTING APPLICATION | AH2: CTRL PRESENCE | AI2: PRESENCE CTRL | AJ2: PRESENCE SCORE CONSEQUENCE | AK2: PRESENCE Code CTRL ZP | AL2: CTRL REFERENTIEL | AM2: REFERENTIEL CTRL | AN2: REFERENTIEL SCORE CONSEQUENCE | AO2: REFERENTIEL Code CTRL ZP | AP2: CTRL VALEUR | AQ2: VALUE CTRL | AR2: VALEUR SCORE CONSEQUENCE | AS2: VALEUR Code CTRL ZP | AT2: CTRL INTRA-OBJET | AU2: INTRA-OBJECT CTRL | AV2: COHERENCE SCORE CONSEQUENCE | AW2: COHERENCE Code CTRL ZP | AX2: CTRL INTER-OBJECT | AY2: INTER-OBJET CTRL | AZ2: Score Consequence | BA2: Code CTRL ZP | BB2: CTRL COHERENCE | BC2: CONSISTENCY CTRL | BD2: Score Consequence | BE2: Code CTRL ZP
A3: Famille de flux et Objet de Collecte véhiculant la donnée / Flow family and data collection object | B3: Numéro séquentiel correspondant au numéro d'ordre de la donnée dans le fichier physique. Invariant dans le temps (toute nouvelle donnée sera ajoutée en fin de fichier) / Sequential number corresponding to the order number of the data in the physical file. Invariant in time (any new data will be added at the end of the file) | C3: Classification de la donnée dans un des blocs structurant l'Objet de Collecte | D3: Classification of the data in one of the blocks structuring the Collection Object. | E3: Référence de la donnée collectée via l'Objet de Collecte. Attribut communément appelé 'Etiquette' / Reference of the data collected via the Collection Object. Attribute commonly referred to as 'Label' | F3: Libellé Métier de la donnée | G3: Data business name | H3: Définition métier de la donnée | I3: Business data definition | J3: Terme métier parent du glossaire métier auquel se rapporte la donnée | K3: Term parent business of the business glossary to which the data relates | L3: Nom technique de la donnée / Technical name of the data | M3: Exigence de présence de la donnée sur le périmètre de Collecte défini. L'information prend la valeur : - Obligatoire si la donnée est exigée - Obligatoire Si si la donnée est exigée dans des conditions définies dans la Règle de Gestion - Facultatif si la donnée n'est pas exigée - NA si la donnée est devenue obsolète et n'est plus collectée sur le domaine de Collecte - A renseigner si l'information n'est pas encore disponible | N3: Requirement to have the data on the defined Collection perimeter. Information is valued: - Mandatory if data is required - Mandatory If the data is required under conditions defined in the Management Rule - Optional if data is not required - NA if the data has become obsolete and is no longer collected on the Collection domain - To be filled if the information is not yet available | O3: Référence du Langage Commun structurant le format autorisé et la nomenclature autorisée. L'information prend la valeur : - LC.NNNN si la donnée s'adosse au LC.NNNN - LC à référencer si la donnée s'adosse à un LC en cours de référencement - NA si la donnée ne s'adosse à aucun LC /A reference to the Common Language structuring the allowed format and the allowed nomenclature. Information is valued: - LC.NNNN if the data is based on LC.NNNN - LC to be referenced if the data is against an LC being referenced - NA if the data does not support any LC. | P3: Table(s)/Rubrique(s) Start porteuse(s) de la nomenclature du Langage Commun lorsque celui ci est référencé. Il peut être multiple. L'information prend la valeur : - TA XXXXX si la donnée s'adosse à la table TA XXXXX - RB XXXXX si la donnée s'adosse à la rubrique RB XXXXX - NA si la donnée ne s'adosse à aucun référentiel Start /Table(s)/Topic(s) Start carrying the nomenclature of the Common Language when it is referenced. It can be multiple. Information is valued: - TA XXXXX if the data is based on the table TA XXXXX - RB XXXXX if the data is based on RB XXXXX - NA if the data does not support any Start referential | Q3: Précisions sur les exigences posées sur la donnée (de type seuils, formules, calculs, règles d'alimentation hors LC...) ou commentaires. En particulier, les exigences posées sur la donnée peuvent porter sur : - sa présence (dans le contrôle) (ne pas reprendre les conditions du contrôle de présence si assez explicite) Nota Bene sur le domaine de valeurs : -- si la donnée peut s'inscrire dans toute la nomenclature d'un Langage Commun, le LC est directement renseigné dans le champ dédié "Référence LC" -- si la donnée s'inscrit dans un domaine de valeurs plus restreint lié au périmètre fonctionnel de l'objet collecté, ce domaine de valeurs strictement autorisé est indiqué ici (contrôle de valeur). L'information prend la valeur NA sans exigences particulières | R3: Details on the requirements of the data (of the threshold type, formulas, calculations, rules of supply excluding LC...) or comments. In particular, the data requirements may relate to: - its presence (in the control) (do not take over the presence control conditions so explicitly) Note Bene on the value domain: — if the data can be inscribed in the entire nomenclature of a Common Language, the LC is directly filled in the dedicated field "LC Reference" — if the data falls within a narrower value domain related to the functional scope of the collected object, this strictly authorized value domain is indicated here (value control). Information is set to NA without any special requirements | S3: Format de la donnée. L'information prend la valeur : - DATE - ALPHA - NUM - A renseigner si l'information n'est pas encore disponible Data format. Information is valued: - DATE - ALPHA - NUM - To be filled if the information is not yet available | T3: Structure de présentation des données de type date, montant et taux. L'information prend la valeur : - "NA" en l'absence de règle de formatage. - "A renseigner" si l'information n'est pas disponible | U3: Date, amount and rate data presentation structure. Information is valued: - "NA" in the absence of a formatting rule. - "To be filled" if the information is not available | V3: Longueur de la donnée La valeur 8 est attendue sur les formats DATE/ Data length Value 8 is expected on DATE formats | W3: Numéro correspondant à la position de la donnée dans la chaine de caractères du fichier physique. Nécessaire que pour les fichiers plats sans séparateurs (PACT par exemple). Elle prend la valeur NA dans les autres cas. / The number that corresponds to the position of the data item in the character string of the physical file. Required only for flat files without separators. It is set to NA in other cases. | X3: Version de la notice dans laquelle la donnée est apparue. L'information prend la valeur: - De la donnée Verbloc figurant dans l'en-tête de la notice - A renseigner si l'information n'est pas encore disponible./ The version of the notice in which the data appeared. Information takes value: - Verbloc data in the header of the notice - To be filled if the information is not yet available. | Y3: Version de la notice dans laquelle la donnée apparaît pour la dernière fois. L'information prend la valeur: - De la donnée Verbloc figurant dans l'en-tête de la notice quand la donnée est devenue obsolète - NA quand la donnée est toujours collectée/ The version of the notice in which the data last appears. Information takes value: - Verbloc data in the header of the record when the data has become obsolete - NA when data is still collected | Z3: Dernière version de publication de la notice présentant la MAJ de la donnée / Latest publication version of the notice where the data was updated | AA3: Liste des usages industriels déclarant exploiter la donnée. L'information prend la valeur : - Usage1, Usage2, Usage3, ..., UsageN si plusieurs usages sont déclarés - NA en l'absence d'usage déclaré - A renseigner si l'information n'est pas encore disponible /List of industrial uses declaring to exploit the data. Information is valued: - Use1, Use2, Use3, ..., UseN if more than one use is declared - NA in the absence of declared use - To be filled if the information is not yet available | AB3: Liste des usages signalant que la donnée est indispensable pour leur fonctionnement. Le processus de production de reporting de ce(s) usage(s) est compromis par l'absence de cette donnée ou par sa non qualité. L'information prend la valeur : - Usage1, Usage2, Usage3, ..., UsageN si plusieurs usages ont déclaré la donnée critique - NA en l'absence de criticité de la donnée quel que soit l'usage - A renseigner si l'information n'est pas encore disponible/ List of uses indicating that the data is essential for their operation. The reporting production process of this use(s) is compromised by the absence of this data or by its non-quality. Information is valued: - Usage1, Usage2, Usage3, ..., UsageN if several uses have declared critical data - NA in the absence of criticality of the data whatever the use - To be filled if the information is not yet available | AC3: Indicateur signalant que la donnée est à caractère personnel. Une donnée à caractère personnel au sens RGPD est une information se rapportant à une personne physique identifiée ou identifiable. Elle peut permettre d'identifier une personne physique directement (exemple : nom et prénom) ou indirectement (exemple : par un numéro de téléphone ou de plaque d'immatriculation, un identifiant tel que le numéro de sécurité sociale, une adresse postale ou courriel). L'information prend la valeur : - Y si la donnée est une donnée à caractère personnel - N dans le cas contraire - A renseigner si l'information n'est pas encore disponible/ Indicator indicating that the data is personal. Personal data in the sense of GDPR is information relating to an identified or identifiable natural person. It can identify a natural person directly (example: first and last names) or indirectly (example: by a telephone or license plate number, an identifier such as a social security number, a postal or email address). Information is valued: - Y if the data is personal data - N otherwise - To be filled if the information is not yet available | AD3: Information concernant les données du P1, M1 et flux passifs seulement. Le périmètre de Collecte précise le domaine fonctionnel auquel se rapporte la Collecte de la donnée. La nature du domaine fonctionnel varie suivant les objets de collecte. L'information peut être de nature: - Type de risque - Nature juridique de la sûreté - NA dans les autres cas/ Information on P1, M1 and liability flow data only. The Collection scope specifies the functional area to which the Data Collection relates. The nature of the functional area varies according to the collection objects. The information may be of a nature: - Risk type - Legal nature of security interest - NA in other cases | AE3: Application en central qui met la donnée à disposition / Central application that makes data available | AF3: Référence de la donnée en provenance de l'application remettante / Reference of data from remitting application
A4: CRRC | B4: 1 | C4: 00 - En-tête du flux | D4: 00 - File header | E4: CRRC H.ENREG | F4: Type d'enregistrement | G4: Type of record | H4: Type d'enregistrement correspondant au bloc En-tête | I4: Type of record corresponding to Header block | J4: ND | K4: ND | L4: ENREG | M4: Obligatoire | N4: Mandatory | O4: NA | P4: NA | Q4: A alimenter à "00" | R4: To be filled with "00" | S4: ALPHA | T4: NA | U4: NA | V4: 2 | W4: NA | X4: 43 | Y4: NA | Z4: NA | AA4: USAGE ZP | AB4: NA | AC4: NA | AD4: NA | AE4: NA | AF4: NA
A5: CRRC | B5: 2 | C5: 00 - En-tête du flux | D5: 00 - File header | E5: CRRC H.IDFICHIER | F5: Identifiant du fichier | G5: File's identifier | H5: Identifiant caractérisant le contenu véhiculé par le fichier et servant à référencer chaque type de fichier échangé dans le Référentiel des Echanges du Groupe afin de favoriser la réutilisation | I5: Identifier characterising the content reported by the file and serving to reference each type of file exchanged in the Group's Exchange Referential to facilitate re-use | J5: ND | K5: ND | L5: IDFICHIER | M5: Obligatoire | N5: Mandatory | O5: NA | P5: NA | Q5: A alimenter à "00000533" | R5: To be filled with "00000533" | S5: ALPHA | T5: NA | U5: NA | V5: 8 | W5: NA | X5: 43 | Y5: NA | Z5: NA | AA5: USAGE ZP | AB5: NA | AC5: NA | AD5: NA | AE5: NA | AF5: NA
A6: CRRC | B6: 3 | C6: 00 - En-tête du flux | D6: 00 - File header | E6: CRRC H.VERFICHIER | F6: Version technique du fichier | G6: File's technical version | H6: Qualifie les modalités techniques de constitution du fichier (positionnel, XML, …) | I6: Characterises the technical modalities for producing the file (positional, XML, etc.) | J6: ND | K6: ND | L6: VERFICHIER | M6: Obligatoire | N6: Mandatory | O6: NA | P6: NA | Q6: A alimenter à "001" | R6: To be filled with "001" | S6: ALPHA | T6: NA | U6: NA | V6: 3 | W6: NA | X6: 43 | Y6: NA | Z6: NA | AA6: USAGE ZP | AB6: NA | AC6: NA | AD6: NA | AE6: NA | AF6: NA
A7: CRRC | B7: 4 | C7: 00 - En-tête du flux | D7: 00 - File header | E7: CRRC H.TIMESTAMP | F7: Horodatage | G7: Timestamp | H7: Date et heure de production du fichier (norme ISO 8601 : séparateur normalisé « T » entre la date et l'heure) | I7: Date and time of the file's production (ISO 8601 standard: normalised separator “T” between the date and time) | J7: ND | K7: ND | L7: TIMESTAMP | M7: Obligatoire | N7: Mandatory | O7: NA | P7: NA | Q7: NA | R7: NA | S7: ALPHA | T7: AAAAMMJJTHHMMSS | U7: YYYYMMDDTHHMMSS | V7: 15 | W7: NA | X7: 43 | Y7: NA | Z7: NA | AA7: USAGE ZP | AB7: NA | AC7: NA | AD7: NA | AE7: NA | AF7: NA
A8: CRRC | B8: 5 | C8: 00 - En-tête du flux | D8: 00 - File header | E8: CRRC H.UOE | F8: Entité émettrice | G8: Issuing entity | H8: Identifiant national de l'entité produisant le fichier (pour son propre compte ou en cas de sous-traitance pour le compte de l'entité déclarante) | I8: National identifier of the entity producing the file (for its own account or, in the event of subcontracting, on behalf of the issuing entity) | J8: ND | K8: ND | L8: UOE | M8: Obligatoire | N8: Mandatory | O8: LC.0003 | P8: RB NM281 | Q8: NA | R8: NA | S8: ALPHA | T8: NA | U8: NA | V8: 5 | W8: NA | X8: 43 | Y8: NA | Z8: 45.00 | AA8: USAGE ZP | AB8: NA | AC8: NA | AD8: NA | AE8: NA | AF8: NA
A9: CRRC | B9: 6 | C9: 00 - En-tête du flux | D9: 00 - File header | E9: CRRC H.UOD | F9: Entité déclarante | G9: Reporting entity | H9: Identifiant national de l'entité à laquelle se rapporte le contenu du fichier (entité porteuse du risque) | I9: National identifier of the entity to which the file's content relates (entity carrying the risk) | J9: ND | K9: ND | L9: UOD | M9: Obligatoire | N9: Mandatory | O9: LC.0003 | P9: RB NM281 | Q9: NA | R9: NA | S9: ALPHA | T9: NA | U9: NA | V9: 5 | W9: NA | X9: 43 | Y9: NA | Z9: NA | AA9: USAGE ZP | AB9: NA | AC9: NA | AD9: NA | AE9: NA | AF9: NA
A10: CRRC | B10: 7 | C10: 00 - En-tête du flux | D10: 00 - File header | E10: CRRC H.NMAPPU | F10: Application émettrice | G10: Issuing application | H10: Code ou nom de l'application ou du job utilisés pour produire le fichier dans le SI de l'entité | I10: Code or name of the application or job used to produce the file in the entity's IT system | J10: ND | K10: ND | L10: NMAPPU | M10: Facultatif | N10: Optional | O10: NA | P10: NA | Q10: NA | R10: NA | S10: ALPHA | T10: NA | U10: NA | V10: 32 | W10: NA | X10: 43 | Y10: NA | Z10: NA | AA10: USAGE ZP | AB10: NA | AC10: NA | AD10: NA | AE10: NA | AF10: NA
A11: CRRC | B11: 8 | C11: 00 - En-tête du flux | D11: 00 - File header | E11: CRRC H.CDBLOC | F11: Code du flux | G11: Flow code | H11: Code du flux correspondant aux objets métier véhiculés par le fichier | I11: Flow code corresponding to the business objects reported by the file | J11: ND | K11: ND | L11: CDBLOC | M11: Obligatoire | N11: Mandatory | O11: NA | P11: NA | Q11: A alimenter à "CRRC" | R11: To filled filled with "CRRC" | S11: ALPHA | T11: NA | U11: NA | V11: 4 | W11: NA | X11: 43 | Y11: NA | Z11: NA | AA11: USAGE ZP | AB11: NA | AC11: NA | AD11: NA | AE11: NA | AF11: NA
A12: CRRC | B12: 9 | C12: 00 - En-tête du flux | D12: 00 - File header | E12: CRRC H.VERBLOC | F12: Version du flux | G12: Flow version | H12: Version du flux correspondant aux objets métier véhiculés par le fichier | I12: Version of flow corresponding to the business objects reported by the file | J12: ND | K12: ND | L12: VERBLOC | M12: Obligatoire | N12: Mandatory | O12: NA | P12: NA | Q12: A alimenter à "45" | R12: To filled filled with "45" | S12: ALPHA | T12: NA | U12: NA | V12: 2 | W12: NA | X12: 43 | Y12: NA | Z12: 45.00 | AA12: USAGE ZP | AB12: NA | AC12: NA | AD12: NA | AE12: NA | AF12: NA
A13: CRRC | B13: 10 | C13: 00 - En-tête du flux | D13: 00 - File header | E13: CRRC H.NUMENV | F13: Numéro d'envoi du fichier | G13: File's dispatch number | H13: Permet de gérer les réemissions | I13: Serves to manage re-issues | J13: ND | K13: ND | L13: NUMENV | M13: Obligatoire | N13: Mandatory | O13: NA | P13: NA | Q13: A alimenter à "00001" et à incrémenter de +1 à chaque réémission | R13: To be filled with "00001"and incrementing by +1 at each reissue | S13: ALPHA | T13: NA | U13: NA | V13: 5 | W13: NA | X13: 43 | Y13: NA | Z13: NA | AA13: USAGE ZP | AB13: NA | AC13: NA | AD13: NA | AE13: NA | AF13: NA
A14: CRRC | B14: 11 | C14: 00 - En-tête du flux | D14: 00 - File header | E14: CRRC H.CRARRETE | F14: Type d'arrêté | G14: Reporting type | H14: Périodicité de l'arrêté | I14: Reporting frequency | J14: ND | K14: ND | L14: CRARRETE | M14: Obligatoire | N14: Mandatory | O14: LC.0056 | P14: TA KVFREQU | Q14: NA | R14: NA | S14: ALPHA | T14: NA | U14: NA | V14: 1 | W14: NA | X14: 43 | Y14: NA | Z14: NA | AA14: USAGE ZP | AB14: NA | AC14: NA | AD14: NA | AE14: NA | AF14: NA
A15: CRRC | B15: 12 | C15: 00 - En-tête du flux | D15: 00 - File header | E15: CRRC H.DTARRETE | F15: Date d'arrêté | G15: Closing date | H15: Date d'arrêté correspondant au contenu du fichier (norme ISO 8601) | I15: Closing date corresponding to the file's content (ISO 8601 standard) | J15: ND | K15: ND | L15: DTARRETE | M15: Obligatoire | N15: Mandatory | O15: NA | P15: NA | Q15: NA | R15: NA | S15: DATE | T15: AAAAMMJJ | U15: YYYYMMDD | V15: 8 | W15: NA | X15: 43 | Y15: NA | Z15: NA | AA15: USAGE ZP | AB15: NA | AC15: NA | AD15: NA | AE15: NA | AF15: NA
... A17: CRRC | B17: 14 | C17: 00 - En-tête du flux | D17: 00 - File header | E17: CRRC H.NMAPPFIN | F17: Application émettrice Finance | G17: Issuing Finance application code | H17: Code de l'application émettrice spécifique à PALMA | I17: Issuing application code specific to PALMA | J17: ND | K17: ND | L17: NMAPPFIN | M17: Facultatif | N17: Optional | O17: NA | P17: NA | Q17: NA | R17: NA | S17: ALPHA | T17: NA | U17: NA | V17: 5 | W17: NA | X17: 43 | Y17: NA | Z17: NA | AA17: USAGE ZP | AB17: NA | AC17: NA | AD17: NA | AE17: NA | AF17: NA
A18: CRRC | B18: 15 | C18: 00 - En-tête du flux | D18: 00 - File header | E18: CRRC H.FILLER | F18: Filler | G18: Filler | H18: Filler pour évolutions futures | I18: Filler for future evolution | J18: ND | K18: ND | L18: FILLER | M18: Facultatif | N18: Optional | O18: NA | P18: NA | Q18: NA | R18: NA | S18: ALPHA | T18: NA | U18: NA | V18: =8000-(SUM(V4:V17)+COUNT(V4:V17)) -> 7886 | W18: NA | X18: 43 | Y18: NA | Z18: NA | AA18: USAGE ZP | AB18: NA | AC18: NA | AD18: NA | AE18: NA | AF18: NA
A19: C1 | B19: 1 | C19: 02 - Caractéristiques d'identification fonctionnelles | D19: 02 - Functional identification characteristics | E19: 0.1 (C1) | F19: Date d'arrêté | G19: Closing date | H19: Correspond à la date d'arrêté des données transmises (dernier jour calendaire du mois) | I19: Represents the cut-off date of the data transmitted (final calendar day of the month) | J19: ND | K19: ND | L19: NA | M19: Obligatoire | N19: Mandatory | O19: NA | P19: NA | Q19: Il doit y avoir unicité de la date d'arrêté au sein du flux | R19: The cut-off date must be the same across the flow | S19: DATE | T19: AAAAMMJJ | U19: YYYYMMDD | V19: 8 | W19: NA | X19: 40 | Y19: NA | Z19: NA | AA19: TIGRE | AB19: ND | AC19: N | AD19: NA | AE19: NA | AF19: NA | AH19: La donnée est obligatoire | AI19: The data is mandatory | AK19: EN0011 | AP19: Si renseignée, pour un même BAAPID, la date d'arrêté doit être supérieure ou égale à la date d'arrêté du dernier lot intégré. (= on n'accepte pas de flux sur un arrêté précédent) Dans la table INTEGRATED_PARENT, pour le même SCOPE_SRC_CD (= BAAPID), la date d'arrêté doit être supérieure ou égale à la dernière date d'arrêté avec le statut « QUALITY_OK ». --- Si renseignée, la date doit être égale au dernier jour calendaire du mois de l'arrêté en cours (ex : 20190131, 20190228, 20190331, etc.) | AQ19: If filled in, for the same BAAPID, the cut-off date must be greater than or equal to the cut-off date of the last integrated batch. (= no flow on previous order accepted) In the INTEGRATED_PARENT table, for the same SCOPE_SRC_CD (= BAAPID), the stop date must be greater than or equal to the last stop date with the status 'QUALITY_OK'. — If filled in, the date must be equal to the last calendar day of the month of the current order (e.g. 20190131, 20190228, 20190331, etc.) | AS19: EN0017 EN0019 | AT19: Si renseignée, pour le même BAAPID, si le dernier lot a un statut "rejeté" ou "à recycler" ou "abandonner", et qu'il n'y a pas d'autres lots en attente, la date d'arrêté doit être inférieure ou égale à la date d'arrêté du dernier lot. Dans la table INTEGRATED_PARENT, pour le même SCOPE_SRC_CD (= BAAPID), la date doit être inférieure ou égale à la dernière date (= STTM_DT) avec le statut « QUALITY_KO », « REJECTED » ou « DECERTIFIED ». | AU19: If filled in for the same BAAPID, if the last batch has a "rejected" or "to recycle" or "abort" status, and there are no other batches pending, the stop date must be less than or equal to the last batch stop date. In the INTEGRATED_PARENT table, for the same SCOPE_SRC_CD (= BAAPID), the date must be less than or equal to the last date (= STTM_DT) with the status “QUALITY_KO”, “REJECTED” or “DECERTIFIED”. | AW19: EN001B
A20: C1 | B20: 2 | C20: 02 - Caractéristiques d'identification fonctionnelles | D20: 02 - Functional identification characteristics | E20: 0.2 (C1) | F20: Entité Porteuse de Risques | G20: Risk taker entity | H20: Correspond au code consolidation comptable de l'Entité porteuse de risque dans les comptes de Crédit Agricole S.A. | I20: Represents the accounting consolidation code of the Entity in the financial statements of Crédit Agricole S.A. | J20: ND | K20: ND | L20: NA | M20: Obligatoire | N20: Mandatory | O20: LC.0003 | P20: TA FI59 | Q20: NA | R20: NA | S20: ALPHA | T20: NA | U20: NA | V20: 5 | W20: NA | X20: 40 | Y20: NA | Z20: NA | AA20: TIGRE | AB20: ND | AC20: N | AD20: NA | AE20: NA | AF20: NA | AH20: La donnée est obligatoire | AI20: The data is mandatory | AK20: EN0021 | AL20: Si renseignée, 1/ Si dans la table START "TA 0990 KVAPPBK", il existe un KVBAPPID pour le KVAPPBK valant la concaténation "Entité porteuse de risque" [EN 0.2] et "Application source" [EN 0.3], alors, les 9 premiers caractères de ce KVBAPPID doivent être présents dans la colonne TMNOMOBE de la table TMTAKOBE. 2/ Si pas présent dans TMTAKOBE, l'entité porteuse de risque [EN 0.2] doit exister dans la colonne TMCCONSU de la table TMTAKOBU. | AM20: If filled, 1/ If in the START table "TA 0990 KVAPPBK", there is a KVBAPPID for the KVAPPBK with the concatenation "risk-carrying Entity" [EN 0.2] and "Source application" [EN 0.3], then the first 9 characters of this KVBAPPID must be present in the TMNOMOBE column of the TMTAKOBE table. 2/ If not present in TMTAKOBE, the risk carrying entity [EN 0.2] shall exist in the TMCCONSU column of the TMTAKOBU table. | AO20: EN0023
A21: C1 | B21: 3 | C21: 02 - Caractéristiques d'identification fonctionnelles | D21: 02 - Functional identification characteristics | E21: 0.3 (C1) | F21: Application source | G21: Source application | H21: Correspond au code du Système d'Information utilisé en local pour générer le flux Dans le flux Grande Clientèle, il faut préfixer par la lettre ‘C' le code application source | I21: Represents the code of the Information System used locally to generate the flow In Corporate flow, the source application code must be prefix with the letter 'C' | J21: ND | K21: ND | L21: NA | M21: Obligatoire | N21: Mandatory | O21: NA | P21: TA KVAPPBK | Q21: La codification est ‘libre' mais doit être obligatoirement préfixé par la valeur "C" (Corporate). Il convient à chaque entité émettrice du flux de déterminer le(s) code(s) ‘Application source' qu'elle utilise et de le(s) porter à la connaissance de la DRG avant première utilisation dans le flux. Une fois communiqué, le code est définitif Il s'agit d'un critère discriminant à l'acquisition des flux par CASA DRG | R21: The code is entered as ‘Free zone' but must be pre-fixed with "C" (Corporate). Every entity issuing flows must determine what ‘Source application' code(s) it uses and inform the Group Risk Management Division thereof prior to using them in the flow. Once notified, the code can't be changed This is a determining factor as regards flow capture by Crédit Agricole S.A. Group Risk Management Division | S21: ALPHA | T21: NA | U21: NA | V21: 12 | W21: NA | X21: 40 | Y21: NA | Z21: NA | AA21: TIGRE | AB21: ND | AC21: N | AD21: NA | AE21: NA | AF21: NA | AH21: La donnée est obligatoire | AI21: The data is mandatory | AK21: EN0031 | AL21: Si elle est renseignée, la valeur doit être connue du Langage Commun associé | AM21: If specified, the value must be known to the associated Common Language | AO21: EN0035
A22: C1 | B22: 4 | C22: 01 - Caractéristiques d'identification techniques | D22: 01 - Technical identification characteristics | E22: 0.4 (C1) | F22: Fréquence de transmission | G22: Transmission frequency | H22: Permet d'identifier le flux dans les traitements | I22: Makes it possible to identify the flow in the treatments | J22: ND | K22: ND | L22: NA | M22: Obligatoire | N22: Mandatory | O22: NA | P22: NA | Q22: La seule valeur admise est 'M' pour mensuel | R22: The only permitted value is 'M' for month | S22: ALPHA | T22: NA | U22: NA | V22: 1 | W22: NA | X22: 40 | Y22: NA | Z22: NA | AA22: TIGRE | AB22: ND | AC22: N | AD22: NA | AE22: NA | AF22: NA | AH22: La donnée est obligatoire | AI22: The data is mandatory | AK22: EN0041 | AP22: Si renseignée, la donnée doit être égale à 'M' ou 'C'. | AQ22: If filled, the data must be equal to 'M' or 'C'. | AS22: EN0043
A23: C1 | B23: 5 | C23: 01 - Caractéristiques d'identification techniques | D23: 01 - Technical identification characteristics | E23: 0.5 (C1) | F23: Date et Heure de traitement | G23: Date and time of processing | H23: Correspond à la date et heure du début du traitement ayant produit le flux | I23: Represents the date and time at which treatment began | J23: ND | K23: ND | L23: NA | M23: Obligatoire | N23: Mandatory | O23: NA | P23: NA | Q23: Unicité obligatoire au sein d'un Lot déterminé | R23: Has to be unique within a specific Batch | S23: ALPHA | T23: NA | U23: NA | V23: 12 | W23: NA | X23: 40 | Y23: NA | Z23: NA | AA23: TIGRE | AB23: ND | AC23: N | AD23: NA | AE23: NA | AF23: NA | AH23: La donnée est obligatoire | AI23: The data is mandatory | AK23: EN0051 | AT23: Si renseignée, la date doit être strictement supérieure à la date de traitement [EN 0.5] du dernier lot traité et non recyclé. (= on ne peut pas intégrer un lot déjà présenté sauf si ce lot avait été mis en recyclage) Dans la table INTEGRATED_PARENT, pour le même SCOPE_SRC_CD (= BAAPID), la date doit être supérieure à la dernière date (= SRC_DT) avec le statut « QUALITY_OK ». | AU23: If filled in, the date must be strictly greater than the treatment date [EN 0.5] of the last batch processed and not recycled. (= a previously submitted batch cannot be included unless the batch has been placed in recycling) In the INTEGRATED_PARENT table, for the same SCOPE_SRC_CD (= BAAPID), the date must be greater than the last date (= SRC_DT) with the status 'QUALITY_OK'. | AW23: EN0056
A24: C1 | B24: 6 | C24: 01 - Caractéristiques d'identification techniques | D24: 01 - Technical identification characteristics | E24: 0.6 (C1) | F24: Type d'enregistrement | G24: Record type | H24: Caractérise le type d'enregistrement remonté par l'entité | I24: Represents the record type reported by the entity | J24: ND | K24: ND | L24: NA | M24: Obligatoire | N24: Mandatory | O24: NA | P24: NA | Q24: La valeur admise est 'C1' pour le domaine Tiers | R24: The permitted value is 'C1' for the External Counterparty section | S24: ALPHA | T24: NA | U24: NA | V24: 2 | W24: NA | X24: 40 | Y24: NA | Z24: NA | AA24: TIGRE | AB24: ND | AC24: N | AD24: NA | AE24: NA | AF24: NA | AH24: La donnée est obligatoire | AI24: The data is mandatory | AK24: EN0061 | AP24: Si renseignée, la donnée doit être égale à 'C1' | AQ24: If filled in, the data must be equal to 'C1' | AS24: EN0061
A25: C1 | B25: 7 | C25: NA | D25: NA | E25: 0.7 (C1) | F25: Nature de flux (Zone réservée DRG) | G25: Nature of flow (Zone reserved for Group Risk Management Division) | H25: Nature de flux (Zone réservée DRG) | I25: Nature of flow (Zone reserved for Group Risk Management Division) | J25: NA | K25: NA | L25: NA | M25: NA | N25: NA | O25: NA | P25: NA | Q25: (Zone réservée DRG) | R25: (Zone reserved for the Group Risk Management Division) | S25: ALPHA | T25: NA | U25: NA | V25: 1 | W25: NA | X25: NA | Y25: 42 | Z25: NA | AA25: NA | AB25: NA | AC25: N | AD25: NA | AE25: NA | AF25: NA
A26: C1 | B26: 8 | C26: NA | D26: NA | E26: 0.99 (C1) | F26: Filler | G26: Filler | H26: Zone libre | I26: Free zone | J26: NA | K26: NA | L26: NA | M26: NA | N26: NA | O26: NA | P26: NA | Q26: Laisser à vide | R26: Leave empty | S26: ALPHA | T26: NA | U26: NA | V26: 9 | W26: NA | X26: NA | Y26: NA | Z26: NA | AA26: NA | AB26: NA | AC26: N | AD26: NA | AE26: NA | AF26: NA
A27: C1 | B27: 9 | C27: 16 - Identification Tiers | D27: 16 - Third party identification | E27: 1.1 (C1) | F27: Identifiant local du tiers | G27: Local identifier for the counterparty | H27: Identifiant du tiers dans le système utilisé pour générer le flux | I27: ID of external counterparty in the system used to generate the flow | J27: ND | K27: ND | L27: NA | M27: Obligatoire | N27: Mandatory | O27: NA | P27: NA | Q27: La codification est à discrétion de chaque entité mais il est nécessaire d'utiliser un identifiant stable Pour un lot déterminé, l'identifiant local doit être unique | R27: The coding is at the discretion of each entity but IDs must be permanent For a given batch, the local ID must be unique | S27: ALPHA | T27: NA | U27: NA | V27: 20 | W27: NA | X27: 40 | Y27: NA | Z27: NA | AA27: TIGRE | AB27: ND | AC27: N | AD27: NA | AE27: NA | AF27: NA
A28: C1 | B28: 10 | C28: 16 - Identification Tiers | D28: 16 - Third party identification | E28: 1.2 (C1) | F28: Identifiant interne du tiers Crédit Agricole | G28: Central identifier for the counterparty | H28: Identifiant du tiers dans le SI DRG IDTCA – (i.e. Identifiant Tiers Central CASA) | I28: ID of the external counterparty in the Group Risk Management Division IT System IDTCA – (i.e. Identifier Central CASA counterparty) | J28: ND | K28: ND | L28: NA | M28: Facultatif | N28: Optional | O28: NA | P28: NA | Q28: Identifiant central fourni par la DRG dans le flux diffusion Tiers (DTG) transmis aux entités émettrices du flux A la première remontée d'un tiers nouvellement créé via le flux , cet identifiant doit être à vide L'identifiant interne est déterminé en central et communiqué aux entités via le flux diffusion Tiers (DTG) et doit être fourni dans le flux du mois suivant (si toujours des engagements sur ce Tiers) | R28: Central ID provided by the Group Risk Management Division in the External Counterparty distribution flow (DTG) sent out to entities issuing flows. When first reporting an external counterparty that has just been added via the flow, this ID must be left empty. The internal ID is determined centrally and sent out to the entities via the External Counterparty distribution flow (DTG) and must be provided in the subsequent month's flow (if there are still commitments vis-à-vis this External Counterparty) | S28: ALPHA | T28: NA | U28: NA | V28: 10 | W28: NA | X28: 40 | Y28: NA | Z28: NA | AA28: TIGRE | AB28: ND | AC28: N | AD28: NA | AE28: NA | AF28: NA
A29: C1 | B29: 11 | C29: NA | D29: NA | E29: 1.4 (C1) | F29: Référence de l'Autorisation Mise En Place | G29: Overall facility reference | H29: Référence de l'Autorisation Mise En Place | I29: Reference code of Arranged facility | J29: NA | K29: NA | L29: NA | M29: NA | N29: NA | O29: NA | P29: NA | Q29: NA | R29: NA | S29: ALPHA | T29: NA | U29: NA | V29: 30 | W29: NA | X29: NA | Y29: 42 | Z29: NA | AA29: NA | AB29: NA | AC29: N | AD29: NA | AE29: NA | AF29: NA
A30: C1 | B30: 12 | C30: NA | D30: NA | E30: 1.6 (C1) | F30: Référence de la ligne de détail de l'Autorisation Mise En Place | G30: Facility detail line reference | H30: Référence de la ligne de détail de l'Autorisation Mise En Place | I30: Reference code of the line of the Arranged facility | J30: NA | K30: NA | L30: NA | M30: NA | N30: NA | O30: NA | P30: NA | Q30: NA | R30: NA | S30: ALPHA | T30: NA | U30: NA | V30: 30 | W30: NA | X30: NA | Y30: 42 | Z30: NA | AA30: NA | AB30: NA | AC30: N | AD30: NA | AE30: NA | AF30: NA
A31: C1 | B31: 13 | C31: NA | D31: NA | E31: 1.8 (C1) | F31: Identifiant de la sûreté reçue | G31: Mitigant identifier | H31: Identifiant de la sûreté reçue | I31: ID of Mitigant received | J31: NA | K31: NA | L31: NA | M31: NA | N31: NA | O31: NA | P31: NA | Q31: NA | R31: NA | S31: ALPHA | T31: NA | U31: NA | V31: 40 | W31: NA | X31: NA | Y31: 42 | Z31: NA | AA31: NA | AB31: NA | AC31: N | AD31: NA | AE31: NA | AF31: NA
A32: C1 | B32: 14 | C32: NA | D32: NA | E32: 1.11 (C1) | F32: Identifiant de l'engagement | G32: Product identifier | H32: Identifiant de l'engagement | I32: ID of commitment | J32: NA | K32: NA | L32: NA | M32: NA | N32: NA | O32: NA | P32: NA | Q32: NA | R32: NA | S32: ALPHA | T32: NA | U32: NA | V32: 40 | W32: NA | X32: NA | Y32: 42 | Z32: NA | AA32: NA | AB32: NA | AC32: N | AD32: NA | AE32: NA | AF32: NA
A33: C1 | B33: 15 | C33: NA | D33: NA | E33: 1.16 (C1) | F33: Référence de la provision sur tiers | G33: Reference for the counterparty provision | H33: Référence de la provision sur tiers | I33: Reference code of the provision for external counterparties | J33: NA | K33: NA | L33: NA | M33: NA | N33: NA | O33: NA | P33: NA | Q33: NA | R33: NA | S33: ALPHA | T33: NA | U33: NA | V33: 40 | W33: NA | X33: NA | Y33: 42 | Z33: NA | AA33: NA | AB33: NA | AC33: N | AD33: NA | AE33: NA | AF33: NA
A34: C1 | B34: 16 | C34: NA | D34: NA | E34: 1.99 (C1) | F34: Filler | G34: Filler | H34: Zone libre | I34: Free zone | J34: NA | K34: NA | L34: NA | M34: NA | N34: NA | O34: NA | P34: NA | Q34: Laisser à vide | R34: Leave empty | S34: ALPHA | T34: NA | U34: NA | V34: 20 | W34: NA | X34: NA | Y34: NA | Z34: NA | AA34: NA | AB34: NA | AC34: N | AD34: NA | AE34: NA | AF34: NA
A35: C1 | B35: 17 | C35: 16 - Identification Tiers | D35: 16 - Third party identification | E35: C1 2.1 | F35: Dénomination sociale INSEE | G35: Counterparty name | H35: Dénomination sociale INSEE pour les tiers français | I35: Corporate name INSEE for French counterparties National's corporate name for other counterparties when it exists; corporate name otherwise | J35: ND | K35: ND | L35: NA | M35: Obligatoire | N35: Mandatory | O35: NA | P35: NA | Q35: Obligatoire pour les tiers français (c'est-à-dire siréné), valoriser le champ avec la dénomination officielle INSEE sinon à vide Donnée sous responsabilité du RUN. | R35: Mandatory for French external counterparties (i.e. those with SIREN numbers). Input the official INSEE corporate name, otherwise leave empty Data owned by the «RUN». | S35: ALPHA | T35: NA | U35: NA | V35: 40 | W35: NA | X35: 40 | Y35: NA | Z35: NA | AA35: TIGRE | AB35: ND | AC35: N | AD35: NA | AE35: NA | AF35: NA
A36: C1 | B36: 18 | C36: 16 - Identification Tiers | D36: 16 - Third party identification | E36: C1 4.22 | F36: Date de génération du CRE ANADEFI | G36: CRE ANADEFI processing Date | H36: Date de génération du CRE ANADEFI | I36: CRE ANADEFI processing Date | J36: ND | K36: ND | L36: NA | M36: Obligatoire | N36: Mandatory | O36: NA | P36: NA | Q36: Obligatoire si le tiers est noté (la note finale retenue du tiers (C1 4.1) est renseignée et différente de 'ND' ) | R36: Mandatory where the assigned rating (C1 4.1) <> ‘ND' or equals spaces | S36: ALPHA | T36: AAAAMMJJHHMMSS | U36: SSAAMMJJHHMMSS | V36: 14 | W36: NA | X36: 40 | Y36: NA | Z36: NA | AA36: TIGRE | AB36: ND | AC36: N | AD36: NA | AE36: NA | AF36: NA
A37: C1 | B37: 19 | C37: 16 - Identification Tiers | D37: 16 - Third party identification | E37: C1 4.30 | F37: Identifiant de l'entreprise mère immédiate | G37: Immediate parent undertaking identifier | H37: Permet d'identifier la maison mère immédiate | I37: Enable the identification of the immediate mother entity | J37: ND | K37: ND | L37: NA | M37: Facultatif | N37: Optional | O37: NA | P37: NA | Q37: Identifiant de l'entreprise mère immédiate correspondant à l'Identifiant Central du Tiers (IDTCA) présent dans le référentiel Tiers & Groupes - Si le tiers représente une succursale d'un établissement dont le siège social à l'étranger (et connu de Tiers et Groupe) alors : C1 4.30 = identifiant IDTCA du siège social (ou maison mère) à l'étranger C1 4.31 = 1 - Si le tiers appartient à un groupe dont le parent immédiat existe (et connu de Tiers et Groupe) alors on renseigne : C1 4.30 = identifiant IDTCA du parent immédiat C1 4.31 = 0 Remarque : dans certains cas, le parent immédiat peut être l'ECU - Sinon, ne pas renseigner l'Identifiant de l'entreprise mère immédiate et l'Indicateur Maison mère identifiée | R37: The Immediate parent undertaking identifier corresponding to the IDTCA of the counterparty in the referential ‘Counterparties & Groups' - If the client of the FTCA represents a branch of a credit insititution whose head office is abroad (and known of the process T&G), then: C10430 = Identifier IDTCA of the head office (or mother entity) abroad C10431 = 1 - If the client of the FTCA is part of a Groupe whose immediate parent exists (and known of the process T&G) then: C10430 = Identifier IDTCA of the immediate parent C10431 = 0 Note : in some cases, the immediate parent may be the ECU - If none of the mis known, the field C10430 remains empty | S37: ALPHA | T37: NA | U37: NA | V37: 10 | W37: NA | X37: 42 | Y37: NA | Z37: NA | AA37: ANACREDIT | AB37: ND | AC37: N | AD37: NA | AE37: NA | AF37: NA
A38: C1 | B38: 20 | C38: 16 - Identification Tiers | D38: 16 - Third party identification | E38: C1 4.31 | F38: Maison Mère Identifiée | G38: Head Office Identifier | H38: Permet d'identifier si le tiers est la maison mère | I38: Enable the identification of the mother entity | J38: ND | K38: ND | L38: NA | M38: Facultatif | N38: Optional | O38: LC.0302 | P38: TA KVMAMEID | Q38: Indicateur 0 ou 1 permettant de préciser que le tiers déclaré est maison mère | R38: Value 0 or 1 aiming at precising if the counterparty is the mother entity | S38: ALPHA | T38: NA | U38: NA | V38: 1 | W38: NA | X38: 42 | Y38: NA | Z38: NA | AA38: ANACREDIT | AB38: ND | AC38: N | AD38: NA | AE38: NA | AF38: NA
A39: C1 | B39: 21 | C39: 16 - Identification Tiers | D39: 16 - Third party identification | E39: C1 4.32 | F39: Adresse : département/division administrative (NUTS) | G39: Address: department/administrative division (NUTS) | H39: Permet d'identifier le département du tiers | I39: Enable the identification of the administrative area of the counterparty | J39: ND | K39: ND | L39: NA | M39: Facultatif | N39: Optional | O39: LC.0265 | P39: TA NMNUTS | Q39: NA | R39: NA | S39: ALPHA | T39: NA | U39: NA | V39: 5 | W39: NA | X39: 42 | Y39: NA | Z39: NA | AA39: ANACREDIT | AB39: ND | AC39: N | AD39: NA | AE39: NA | AF39: NA
A40: C1 | B40: 22 | C40: 16 - Identification Tiers | D40: 16 - Third party identification | E40: C1 4.33 | F40: État d'avancement des procédures judiciaires | G40: Status of legal Proceeding | H40: Permet d'identifier si une procédure judiciaire est en cours | I40: Enable to indicate if a legal procedure is ongoing | J40: ND | K40: ND | L40: NA | M40: Facultatif | N40: Optional | O40: LC.0226 | P40: TA KVINPROC | Q40: NA | R40: NA | S40: ALPHA | T40: NA | U40: NA | V40: 1 | W40: NA | X40: 42 | Y40: NA | Z40: NA | AA40: ANACREDIT | AB40: ND | AC40: N | AD40: NA | AE40: NA | AF40: NA
A41: C1 | B41: 23 | C41: 16 - Identification Tiers | D41: 16 - Third party identification | E41: C1 4.34 | F41: Date d'ouverture de la procédure judiciaire | G41: Date of initiation of legal proceedings | H41: Informe sur la date de début de cette procédure | I41: Indicate the original date of the legal procedure | J41: ND | K41: ND | L41: NA | M41: Obligatoire | N41: Mandatory | O41: NA | P41: NA | Q41: Si la valeur du champ « Etat d'avancement des procédures judiciaires » est différente de 0 ou 1 alors date obligatoire sinon le champ doit rester à vide | R41: Mandatory where status of legal proceeding different from 0 or 1 | S41: DATE | T41: AAAAMMJJ | U41: YYYYMMDD | V41: 8 | W41: NA | X41: 42 | Y41: NA | Z41: NA | AA41: ANACREDIT | AB41: ND | AC41: N | AD41: NA | AE41: NA | AF41: NA
...

Sheet Ctrl cohérence-consistency ctr 
B2: Contrôles de cohérence | L2: Consistency controls
B4: Principe : Ces contrôles consistent à vérifier que la valeur portée par une donnée pivot est cohérente avec des données associées. Un contrôle de cohérence peut porter sur : · Une ou plusieurs données d’un même objet de collecte · Plusieurs données de plusieurs objets de collecte | L4: Principle: These controls are to ensure that the value of a pivot data is consistent with associated data. A consistency check may cover: ・ One or more data from the same data collection object ・ Several data from several data collection objects
B6: Périmètre d'application : - CRR Corporate - CRR Retail Agrégé - CRR Adapté | L6: Scope of application: - CRR Corporate - CRR Aggregated Retail - Adapted CRR
B8: Fonctionnement : - Contrôles exécutés en étape E4.4 des traitements ZP (après mise au modèle) - Contrôles paramétrés en score 6TA (non bloquant) - Les combinaisons de valeurs conformes sont précisées ci-dessous pour chaque contrôle sauf contrôle TC0C03 pour lequel sont précisées les combinaisons en anomalie. En dehors des combinaisons conformes, la Zone de Partage recensera une anomalie. | L8: Functions: - Checks performed in step E4.4 of ZP treatments (after the model has been set) - Controls configured in scoring 6TA (non-blocking) - The combinations of conforming values are specified below for each control except control TC0C03 for which the combinations in anomaly are specified. Apart from the compliant combinations, the Sharing Zone will identify an anomaly.
B10: Légende : | L10: Legend:
B11: * : Quelle que soit la valeur | L11: * Whatever the value
B12: Donnée pivot | L12: Pivot data
B13: Donnée complémentaire | L13: Additional data
B17: Contrôle TC0C01 : Cohérence Tiers en défaut/Engagement douteux | L17: Control TC0C01 : Third party consistency in default/doubtful Funds in use
B18: Description du contrôle | D18: Périmètre | L18: Description of control | N18: Scope
B19: Ce contrôle consiste à vérifier la convergence entre les douteux (de niveau engagement) et les défauts (de niveau client) | D19: Grande Clientèle et Clientèle de détail en méthode IRB | L19: This control consists in checking the convergence between doubtful (funds in use-level) and flawed (customer-level) assets | N19: Corporate customers and Retail customers in IRB method
B21: P1/P2 | L21: P1/P2
C23: control entry point | M23: control entry point
B24: Identifiant de l'engagement (1.11 (P1), 1.11 (P2)) | C24: Méthodologie Bâloise (P1 1.1, P2 1.1) | D24: Note Interne Retenue (C1 4.1) | E24: Date d'entrée en défaut (C1 4.15) | F24: Indicateur 'Engagement Douteux' (P1 5.2, P2 5.2) | G24: Date de passage en 'Engagement douteux' (P1 5.3, P2 5.3) | L24: Commitment ID (1.11 (P1), 1.11 (P2)) | M24: Basel Methodology (P1 1.1, P2 1.1) | N24: Internal Rating Assigned (C1 4.1) | O24: Default Entry Date (C1 4.15) | P24: Doubtful Commitment' Indicator (P1 5.2, P2 5.2) | Q24: Date of Transfer to 'Doubtful Commitment' (P1 5.3, P2 5.3)
B25: * | C25: 'IRB A' or 'IRB F' | D25: F or Z | E25: < Date d'arrêté - 1 mois | F25: Y | G25: (non vide) | L25: * | M25: 'IRB A' or 'IRB F' | N25: F or Z | O25: < Date d'arrêté - 1 mois | P25: Y | Q25: (non vide)
C27: control entry point | M27: control entry point
B28: Indicateur 'Engagement Douteux' (P1 5.2, P2 5.2) | C28: Méthodologie Bâloise (P1 1.1, P2 1.1) | D28: Date de passage en 'Engagement douteux' (P1 5.3, P2 5.3) | E28: Note Interne Retenue (C1 4.1) | F28: Date d'entrée en défaut (C1 4.15) | L28: Doubtful Commitment' Indicator (P1 5.2, P2 5.2) | M28: Basel Methodology (P1 1.1, P2 1.1) | N28: Date of Transfer to 'Doubtful Commitment' (P1 5.3, P2 5.3) | O28: Internal Rating Assigned (C1 4.1) | P28: Default Entry Date (C1 4.15)
B29: Y | C29: 'IRB A' or 'IRB F' | D29: < Date d'arrêté - 1 mois | E29: F or Z | F29: (non vide) | L29: Y | M29: 'IRB A' or 'IRB F' | N29: < Date d'arrêté - 1 mois | O29: F or Z | P29: (non vide)
B33: Contrôle TC0C03 : Cohérence Données de détermination de la CAP | L33: Control TC0C03 : Consistency CAP determination data
B34: Description du contrôle | D34: Périmètre | L34: Description of control | N34: Scope
B35: Le contrôle consiste à vérifier la cohérence entre les données qui permettent de déterminer la Classe d’Actifs de Pondération (CAP) | D35: Grande Clientèle et Clientèle de détail | L35: The control consists in checking the consistency between the data used to determine the Risk Weighting Asset Class () | N35: Corporate customers and Retail customers
B37: P1/P2 | L37: P1/P2
B39: Portefeuille Bâle Opération (P1 2.18, P2 2.18) | C39: Portefeuille Bâle Tiers (C1 4.7) | D39: Catégorie de contrepartie (C1 4.6) | E39: Méthodologie Bâloise (P1 1.1, P2 1.1) | L39: Basel Portfolio Operation (P1 2.18, P2 2.18) | M39: Basel Portfolio Counterparty (C1 4.7) | N39: Counterparty Category (C1 4.6) | O39: Basel Methodology (P1 1.1, P2 1.1)
B40: 061, 062, 063, 064 , 065, 070, 077 or 090 | C40: 022, 030 or 050 | D40: * except PCG10, PC21, PCG22, PCG23, PCG24 | E40: IRB A, IRB F or STD | L40: 061, 062, 063, 064 , 065, 070, 077 or 090 | M40: 022, 030 or 050 | N40: * except PCG10, PC21, PCG22, PCG23, PCG24 | O40: IRB A, IRB F or STD
B41: 061, 062, 063, 064 , 065, 070, 077 or 090 | C41: 040 | D41: * except PCG10, PC21, PCG22, PCG23, PCG24 | E41: IRB F or STD | L41: 061, 062, 063, 064 , 065, 070, 077 or 090 | M41: 040 | N41: * except PCG10, PC21, PCG22, PCG23, PCG24 | O41: IRB F or STD
B42: 080 or 081 | C42: 022, 030, 040 or 050 | D42: * except PCG10, PC21, PCG22, PCG23, PCG24 | E42: STD | L42: 080 or 081 | M42: 022, 030, 040 or 050 | N42: * except PCG10, PC21, PCG22, PCG23, PCG24 | O42: STD
B43: 900 | C43: 040 | D43: ACG12, ACG13, ACG20, ACG31, ACG32, ACG42, BCG23, BCG24, BCG25, BCG26, BCG27, BCG28, BCG29, FCG11, FCG12, FCG13, FCG21 , FCG24 or SCG10 | E43: IRB F or STD | L43: 900 | M43: 040 | N43: ACG12, ACG13, ACG20, ACG31, ACG32, ACG42, BCG23, BCG24, BCG25, BCG26, BCG27, BCG28, BCG29, FCG11, FCG12, FCG13, FCG21 , FCG24 or SCG10 | O43: IRB F or STD
B44: 900 | C44: 050 | D44: ACG11, ACG12, ACG13, ACG20, SCG10, SCG11 or BCG10 | E44: IRB A, IRB F or STD | L44: 900 | M44: 050 | N44: ACG11, ACG12, ACG13, ACG20, SCG10, SCG11 or BCG10 | O44: IRB A, IRB F or STD
B45: 900 | C45: 030 | D45: SCG20, ECG11, ECG13, ECG21, ECG31, ECG41, FCG22, FCG23, FCG31, FCG32, FCG33, ICG11, ICG12, ICG21, ICG22, ICG23, ICG30, MCG11, MCG12, MCG21, MCG22, MCG31, MCG32, MCG33, MCG34, MCG35, MCG36, MCG41, MCG42, MCG43, MCG44 or MCG60 | E45: IRB A, IRB F or STD | L45: 900 | M45: 030 | N45: SCG20, ECG11, ECG13, ECG21, ECG31, ECG41, FCG22, FCG23, FCG31, FCG32, FCG33, ICG11, ICG12, ICG21, ICG22, ICG23, ICG30, MCG11, MCG12, MCG21, MCG22, MCG31, MCG32, MCG33, MCG34, MCG35, MCG36, MCG41, MCG42, MCG43, MCG44 or MCG60 | O45: IRB A, IRB F or STD
B46: 900 | C46: 022 | D46: ECG12, ECG32 or ECG42 | E46: IRB A, IRB F or STD | L46: 900 | M46: 022 | N46: ECG12, ECG32 or ECG42 | O46: IRB A, IRB F or STD
B49: Contrôle TC0C11 : Cohérence NATO/Domaine CRR | L49: Control TC0C11 : NATO/CRR domain consistency
B50: Description du contrôle | D50: Périmètre | L50: Description of control | N50: Scope
B51: Ce contrôle consiste à vérifier l’utilisation de la NATO avec les domaines du CRR pour chacun des flux CRR transmis | D51: Grande Clientèle, Clientèle de détail et Alimentation adaptée | L51: This control consists in checking the use of the NATO with the CRR domains for each of the CRR flows transmitted | N51: Corporate customers, Retail customers and Adapted food
B53: P1/P2/M1 | L53: P1/P2/M1
C55: Nature d'Opération (P1 2.29, P2 2.29, M1 2.3) | D55: Objet de collecte | M55: NATure of funds in use transaction (P1 2.29, P2 2.29, M1 2.3) | N55: Business object
B56: P1 2.29 | C56: NA010, NA011, NA012, NA020, NA021, NA022, NA300, NA311, NA312, NA321, NA322, NA323, NA330, NA341, NA342, NA343, NA344, NA350, NA361, NA362, NA363, NA364, NA365, NA366, NA367, NA368, NA369, NA370, NA371, NAT41, NAT42, NAT43, NAT44, NAT06, NAT07, NA100, NA101, NA102 | D56: P1 | L56: P1 2.29 | M56: NA010, NA011, NA012, NA020, NA021, NA022, NA300, NA311, NA312, NA321, NA322, NA323, NA330, NA341, NA342, NA343, NA344, NA350, NA361, NA362, NA363, NA364, NA365, NA366, NA367, NA368, NA369, NA370, NA371, NAT41, NAT42, NAT43, NAT44, NAT06, NAT07, NA100, NA101, NA102 | N56: P1
B57: P2 2.29 | C57: NAT06, NAT07 | D57: P2 | L57: P2 2.29 | M57: NAT06, NAT07 | N57: P2
B58: M1 2.3 | C58: NAT81, NAT82, NAT83, NAT84, NAT85 | D58: M1 | L58: M1 2.3 | M58: NAT81, NAT82, NAT83, NAT84, NAT85 | N58: M1
B63: Contrôle TC0C14 : Cohérence Portefeuille Bâle Tiers / Domaine CRRC | L63: Control TC0C14 : Third Parties Basel Portfolio / CRRC perimeter consistency
B64: Description du contrôle | D64: Périmètre | L64: Description of control | N64: Scope
...
